File: reference/original_matlab_code/ViscoelasticAnalysis/Sample Instron Files/Specimen_RawData_1.csv
Time,Extension,Load
(sec),(mm),(N)
0.00000,9.96269,0.00006
0.20000,9.96061,-0.00008
0.40000,9.94498,-0.00175
0.60000,9.93373,-0.00310
0.80000,9.92290,-0.00447
1.00000,9.91269,-0.00584
1.20000,9.90269,-0.00732
1.40000,9.89311,-0.00880
1.60000,9.88290,-0.01051
1.80000,9.87311,-0.01228
2.00000,9.86290,-0.01412
2.20000,9.85311,-0.01600
2.40000,9.84290,-0.01799
2.60000,9.83332,-0.02004
2.80000,9.82311,-0.02219
3.00000,9.81311,-0.02442
3.20000,9.80290,-0.02673
3.40000,9.79290,-0.02908
3.60000,9.78311,-0.03143
3.80000,9.77290,-0.03382
4.00000,9.76248,-0.03648
4.20000,9.75269,-0.03898
4.40000,9.74269,-0.04163
4.60000,9.73228,-0.04443
4.80000,9.72248,-0.04718
5.00000,9.71269,-0.04987
5.20000,9.70290,-0.05271
5.40000,9.69290,-0.05559
5.60000,9.68269,-0.05872
5.80000,9.67290,-0.06160
6.00000,9.66332,-0.06452
6.20000,9.65290,-0.06774
6.40000,9.64290,-0.07079
6.60000,9.63311,-0.07374
6.80000,9.62332,-0.07661
7.00000,9.61290,-0.07954
7.20000,9.60269,-0.08287
7.40000,9.59332,-0.08606
7.60000,9.58332,-0.08959
7.80000,9.57227,-0.09343
8.00000,9.56269,-0.09689
8.20000,9.55290,-0.10024
8.40000,9.54332,-0.10375
8.60000,9.53248,-0.10769
8.80000,9.52248,-0.11151
9.00000,9.51290,-0.11507
9.20000,9.50311,-0.11875
9.40000,9.49290,-0.12267
9.60000,9.48290,-0.12664
9.80000,9.47290,-0.13062
10.00000,9.46311,-0.13453
10.01600,9.46228,-0.13479
10.21600,9.46082,-0.13411
10.41600,9.46082,-0.13236
10.61600,9.46082,-0.13084
10.81600,9.46082,-0.12950
11.01600,9.46082,-0.12829
11.21600,9.46082,-0.12714
11.41600,9.46123,-0.12603
11.61600,9.46123,-0.12502
11.81600,9.46144,-0.12404
12.01600,9.46165,-0.12307
12.21600,9.46186,-0.12211
12.41600,9.46186,-0.12133
12.61600,9.46186,-0.12046
12.81600,9.46207,-0.11966
13.01600,9.46207,-0.11887
13.21600,9.46207,-0.11816
13.41600,9.46207,-0.11741
13.61600,9.46228,-0.11674
13.81600,9.46228,-0.11602
14.01600,9.46228,-0.11538
14.21600,9.46228,-0.11476
14.41600,9.46228,-0.11412
14.61600,9.46228,-0.11352
14.81600,9.46228,-0.11295
15.01600,9.46228,-0.11218
15.21600,9.46228,-0.11155
15.41600,9.46228,-0.11103
15.61600,9.46228,-0.11047
15.81600,9.46228,-0.10991
16.01600,9.46228,-0.10937
16.21600,9.46228,-0.10884
16.41600,9.46228,-0.10836
16.61600,9.46228,-0.10784
16.81600,9.46228,-0.10736
17.01600,9.46228,-0.10689
17.21600,9.46228,-0.10634
17.41600,9.46228,-0.10590
17.61600,9.46228,-0.10542
17.81600,9.46228,-0.10498
18.01600,9.46228,-0.10450
18.21600,9.46228,-0.10402
18.41600,9.46228,-0.10363
18.61600,9.46228,-0.10319
18.81600,9.46228,-0.10274
19.01600,9.46228,-0.10230
19.21600,9.46228,-0.10190
19.41600,9.46228,-0.10146
19.61600,9.46228,-0.10107
19.81600,9.46228,-0.10064
20.01600,9.46228,-0.10025
20.21600,9.46228,-0.09984
20.41600,9.46228,-0.09950
20.61600,9.46228,-0.09912
20.81600,9.46228,-0.09871
21.01600,9.46228,-0.09835
21.21600,9.46228,-0.09797
21.41600,9.46228,-0.09757
21.61600,9.46228,-0.09720
21.81600,9.46228,-0.09686
22.01600,9.46228,-0.09649
22.21600,9.46228,-0.09613
22.41600,9.46228,-0.09579
22.61600,9.46228,-0.09545
22.81600,9.46228,-0.09505
23.01600,9.46228,-0.09474
23.21600,9.46228,-0.09442
23.41600,9.46228,-0.09406
23.61600,9.46228,-0.09375
23.81600,9.46228,-0.09345
24.01600,9.46228,-0.09309
24.21600,9.46228,-0.09280
24.41600,9.46228,-0.09251
24.61600,9.46228,-0.09219
24.81600,9.46228,-0.09185
25.01600,9.46228,-0.09157
25.21600,9.46228,-0.09124
25.41600,9.46228,-0.09094
25.61600,9.46228,-0.09063
25.81600,9.46228,-0.09038
26.01600,9.46228,-0.09010
26.21600,9.46228,-0.08979
26.41600,9.46228,-0.08954
26.61600,9.46228,-0.08923
26.81600,9.46228,-0.08894
27.01600,9.46228,-0.08860
27.21600,9.46228,-0.08838
27.41600,9.46228,-0.08811
27.61600,9.46228,-0.08779
27.81600,9.46228,-0.08756
28.01600,9.46228,-0.08726
28.21600,9.46228,-0.08702
28.41600,9.46228,-0.08676
28.61600,9.46228,-0.08649
28.81600,9.46228,-0.08622
29.01600,9.46228,-0.08595
29.21600,9.46228,-0.08572
29.41600,9.46228,-0.08547
29.61600,9.46228,-0.08520
29.81600,9.46228,-0.08499
30.01600,9.46228,-0.08475
30.21600,9.46228,-0.08448
30.41600,9.46228,-0.08422
30.61600,9.46228,-0.08399
30.81600,9.46228,-0.08378
31.01600,9.46228,-0.08351
31.21600,9.46228,-0.08330
31.41600,9.46228,-0.08303
31.61600,9.46228,-0.08282
31.81600,9.46228,-0.08259
32.01600,9.46228,-0.08237
32.21600,9.46228,-0.08211
32.41600,9.46228,-0.08193
32.61600,9.46228,-0.08171
32.81600,9.46228,-0.08147
33.01600,9.46228,-0.08127
33.21600,9.46228,-0.08104
33.41600,9.46228,-0.08077
33.61600,9.46228,-0.08058
33.81600,9.46228,-0.08038
34.01600,9.46228,-0.08015
34.21600,9.46228,-0.07994
34.41600,9.46228,-0.07979
34.61600,9.46228,-0.07956
34.81600,9.46228,-0.07934
35.01600,9.46228,-0.07913
35.21600,9.46228,-0.07895
35.41600,9.46228,-0.07875
35.61600,9.46228,-0.07854
35.81600,9.46228,-0.07833
36.01600,9.46228,-0.07811
36.21600,9.46228,-0.07794
36.41600,9.46228,-0.07776
36.61600,9.46228,-0.07755
36.81600,9.46228,-0.07737
37.01600,9.46228,-0.07716
37.21600,9.46228,-0.07699
37.41600,9.46228,-0.07678
37.61600,9.46228,-0.07660
37.81600,9.46228,-0.07644
38.01600,9.46228,-0.07627
38.21600,9.46228,-0.07603
38.41600,9.46228,-0.07591
38.61600,9.46228,-0.07571
38.81600,9.46228,-0.07552
39.01600,9.46228,-0.07536
39.21600,9.46228,-0.07512
39.41600,9.46228,-0.07497
39.61600,9.46228,-0.07479
39.81600,9.46228,-0.07464
40.01600,9.46228,-0.07443
40.21600,9.46228,-0.07427
40.41600,9.46228,-0.07415
40.61600,9.46228,-0.07395
40.81600,9.46228,-0.07378
41.01600,9.46228,-0.07362
41.21600,9.46228,-0.07349
41.41600,9.46228,-0.07328
41.61600,9.46228,-0.07311
41.81600,9.46228,-0.07299
42.01600,9.46228,-0.07283
42.21600,9.46228,-0.07266
42.41600,9.46228,-0.07249
42.61600,9.46228,-0.07236
42.81600,9.46228,-0.07219
43.01600,9.46228,-0.07209
43.21600,9.46228,-0.07190
43.41600,9.46228,-0.07171
43.61600,9.46228,-0.07157
43.81600,9.46228,-0.07143
44.01600,9.46228,-0.07130
44.21600,9.46228,-0.07113
44.41600,9.46228,-0.07098
44.61600,9.46228,-0.07084
44.81600,9.46228,-0.07074
45.01600,9.46228,-0.07054
45.21600,9.46228,-0.07039
45.41600,9.46228,-0.07027
45.61600,9.46228,-0.07014
45.81600,9.46228,-0.06998
46.01600,9.46228,-0.06984
46.21600,9.46228,-0.06971
46.41600,9.46228,-0.06954
46.61600,9.46228,-0.06939
46.81600,9.46228,-0.06930
47.01600,9.46228,-0.06915
47.21600,9.46228,-0.06903
47.41600,9.46228,-0.06887
47.61600,9.46228,-0.06875
47.81600,9.46228,-0.06861
48.01600,9.46228,-0.06846
48.21600,9.46228,-0.06832
48.41600,9.46228,-0.06815
48.61600,9.46228,-0.06801
48.81600,9.46228,-0.06790
49.01600,9.46228,-0.06777
49.21600,9.46228,-0.06765
49.41600,9.46228,-0.06749
49.61600,9.46228,-0.06737
49.81600,9.46228,-0.06721
50.01600,9.46228,-0.06710
50.21600,9.46228,-0.06698
50.41600,9.46228,-0.06686
50.61600,9.46228,-0.06672
50.81600,9.46228,-0.06658
51.01600,9.46228,-0.06647
51.21600,9.46228,-0.06636
51.41600,9.46228,-0.06623
51.61600,9.46228,-0.06609
51.81600,9.46228,-0.06601
52.01600,9.46228,-0.06586
52.21600,9.46228,-0.06572
52.41600,9.46228,-0.06561
52.61600,9.46228,-0.06547
52.81600,9.46228,-0.06539
53.01600,9.46228,-0.06527
53.21600,9.46228,-0.06516
53.41600,9.46228,-0.06503
53.61600,9.46228,-0.06494
53.81600,9.46228,-0.06480
54.01600,9.46228,-0.06470
54.21600,9.46228,-0.06459
54.41600,9.46228,-0.06449
54.61600,9.46228,-0.06437
54.81600,9.46228,-0.06428
55.01600,9.46228,-0.06412
55.21600,9.46228,-0.06407
55.41600,9.46228,-0.06391
55.61600,9.46228,-0.06383
55.81600,9.46228,-0.06370
56.01600,9.46228,-0.06357
56.21600,9.46228,-0.06351
56.41600,9.46228,-0.06338
56.61600,9.46228,-0.06323
56.81600,9.46228,-0.06317
57.01600,9.46228,-0.06306
57.21600,9.46228,-0.06294
57.41600,9.46228,-0.06285
57.61600,9.46228,-0.06275
57.81600,9.46228,-0.06267
58.01600,9.46228,-0.06252
58.21600,9.46228,-0.06246
58.41600,9.46228,-0.06235
58.61600,9.46228,-0.06222
58.81600,9.46228,-0.06213
59.01600,9.46228,-0.06204
59.21600,9.46228,-0.06192
59.41600,9.46228,-0.06183
59.61600,9.46228,-0.06170
59.81600,9.46228,-0.06160
60.01600,9.46228,-0.06149
60.21600,9.46228,-0.06144
60.41600,9.46228,-0.06131
60.61600,9.46228,-0.06123
60.81600,9.46228,-0.06111
61.01600,9.46228,-0.06102
61.21600,9.46228,-0.06097
61.41600,9.46228,-0.06083
61.61600,9.46228,-0.06074
61.81600,9.46228,-0.06069
62.01600,9.46228,-0.06056
62.21600,9.46228,-0.06045
62.41600,9.46228,-0.06043
62.61600,9.46228,-0.06030
62.81600,9.46228,-0.06022
63.01600,9.46228,-0.06010
63.21600,9.46228,-0.06000
63.41600,9.46228,-0.05993
63.61600,9.46228,-0.05982
63.81600,9.46228,-0.05975
64.01600,9.46228,-0.05963
64.21600,9.46228,-0.05955
64.41600,9.46228,-0.05947
64.61600,9.46228,-0.05939
64.81600,9.46228,-0.05927
65.01600,9.46228,-0.05916
65.21600,9.46228,-0.05909
65.41600,9.46228,-0.05902
65.61600,9.46228,-0.05888
65.81600,9.46228,-0.05884
66.01600,9.46228,-0.05870
66.21600,9.46228,-0.05865
66.41600,9.46228,-0.05859
66.61600,9.46228,-0.05844
66.81600,9.46228,-0.05841
67.01600,9.46228,-0.05833
67.21600,9.46228,-0.05821
67.41600,9.46228,-0.05813
67.61600,9.46228,-0.05803
67.81600,9.46228,-0.05796
68.01600,9.46228,-0.05787
68.21600,9.46228,-0.05775
68.41600,9.46228,-0.05771
68.61600,9.46228,-0.05761
68.81600,9.46228,-0.05752
69.01600,9.46228,-0.05746
69.21600,9.46228,-0.05738
69.41600,9.46228,-0.05730
69.61600,9.46228,-0.05720
69.81600,9.46228,-0.05715
70.01600,9.46228,-0.05704
70.21600,9.46228,-0.05696
70.41600,9.46228,-0.05692
70.61600,9.46228,-0.05682
70.81600,9.46228,-0.05672
71.01600,9.46228,-0.05666
71.21600,9.46228,-0.05659
71.41600,9.46228,-0.05651
71.61600,9.46228,-0.05645
71.81600,9.46228,-0.05640
72.01600,9.46228,-0.05626
72.21600,9.46228,-0.05621
72.41600,9.46228,-0.05616
72.61600,9.46228,-0.05604
72.81600,9.46228,-0.05597
73.01600,9.46228,-0.05586
73.21600,9.46228,-0.05583
73.41600,9.46228,-0.05574
73.61600,9.46228,-0.05567
73.81600,9.46228,-0.05559
74.01600,9.46228,-0.05551
74.21600,9.46228,-0.05546
74.41600,9.46228,-0.05539
74.61600,9.46228,-0.05528
74.81600,9.46228,-0.05520
75.01600,9.46228,-0.05512
75.21600,9.46228,-0.05506
75.41600,9.46228,-0.05501
75.61600,9.46228,-0.05493
75.81600,9.46228,-0.05485
76.01600,9.46228,-0.05478
76.21600,9.46228,-0.05472
76.41600,9.46228,-0.05460
76.61600,9.46228,-0.05458
76.81600,9.46228,-0.05450
77.01600,9.46228,-0.05443
77.21600,9.46228,-0.05438
77.41600,9.46228,-0.05428
77.61600,9.46228,-0.05422
77.81600,9.46228,-0.05412
78.01600,9.46228,-0.05404
78.21600,9.46228,-0.05401
78.41600,9.46228,-0.05392
78.61600,9.46228,-0.05387
78.81600,9.46228,-0.05374
79.01600,9.46228,-0.05371
79.21600,9.46228,-0.05366
79.41600,9.46228,-0.05358
79.61600,9.46228,-0.05352
79.81600,9.46228,-0.05345
80.01600,9.46228,-0.05338
80.21600,9.46228,-0.05328
80.41600,9.46228,-0.05325
80.61600,9.46228,-0.05323
80.81600,9.46228,-0.05311
81.01600,9.46228,-0.05304
81.21600,9.46228,-0.05296
81.41600,9.46228,-0.05292
81.61600,9.46228,-0.05286
81.81600,9.46228,-0.05280
82.01600,9.46228,-0.05269
82.21600,9.46228,-0.05268
82.41600,9.46228,-0.05261
82.61600,9.46228,-0.05253
82.81600,9.46228,-0.05246
83.01600,9.46228,-0.05238
83.21600,9.46228,-0.05235
83.41600,9.46228,-0.05228
83.61600,9.46228,-0.05222
83.81600,9.46228,-0.05214
84.01600,9.46228,-0.05208
84.21600,9.46228,-0.05205
84.41600,9.46228,-0.05198
84.61600,9.46228,-0.05192
84.81600,9.46228,-0.05184
85.01600,9.46228,-0.05180
85.21600,9.46228,-0.05167
85.41600,9.46228,-0.05163
85.61600,9.46228,-0.05161
85.81600,9.46228,-0.05157
86.01600,9.46228,-0.05150
86.21600,9.46228,-0.05143
86.41600,9.46228,-0.05143
86.61600,9.46228,-0.05128
86.81600,9.46228,-0.05128
87.01600,9.46228,-0.05126
87.21600,9.46228,-0.05118
87.41600,9.46228,-0.05112
87.61600,9.46228,-0.05110
87.81600,9.46228,-0.05104
88.01600,9.46228,-0.05096
88.21600,9.46228,-0.05091
88.41600,9.46228,-0.05086
88.61600,9.46228,-0.05083
88.81600,9.46228,-0.05073
89.01600,9.46228,-0.05070
89.21600,9.46228,-0.05063
89.41600,9.46228,-0.05056
89.61600,9.46228,-0.05052
89.81600,9.46228,-0.05049
90.01600,9.46228,-0.05037
90.21600,9.46228,-0.05037
90.41600,9.46228,-0.05031
90.61600,9.46228,-0.05029
90.81600,9.46228,-0.05019
91.01600,9.46228,-0.05013
91.21600,9.46228,-0.05008
91.41600,9.46228,-0.05003
91.61600,9.46228,-0.04998
91.81600,9.46228,-0.04990
92.01600,9.46228,-0.04984
92.21600,9.46228,-0.04977
92.41600,9.46228,-0.04974
92.61600,9.46228,-0.04968
92.81600,9.46228,-0.04965
93.01600,9.46228,-0.04960
93.21600,9.46228,-0.04957
93.41600,9.46228,-0.04953
93.61600,9.46228,-0.04948
93.81600,9.46228,-0.04945
94.01600,9.46228,-0.04940
94.21600,9.46228,-0.04935
94.41600,9.46228,-0.04930
94.61600,9.46228,-0.04926
94.81600,9.46228,-0.04920
95.01600,9.46228,-0.04916
95.21600,9.46228,-0.04912
95.41600,9.46228,-0.04905
95.61600,9.46228,-0.04900
95.81600,9.46228,-0.04895
96.01600,9.46228,-0.04891
96.21600,9.46228,-0.04885
96.41600,9.46228,-0.04880
96.61600,9.46228,-0.04875
96.81600,9.46228,-0.04871
97.01600,9.46228,-0.04865
97.21600,9.46228,-0.04858
97.41600,9.46228,-0.04851
97.61600,9.46228,-0.04851
97.81600,9.46228,-0.04847
98.01600,9.46228,-0.04841
98.21600,9.46228,-0.04839
98.41600,9.46228,-0.04831
98.61600,9.46228,-0.04829
98.81600,9.46228,-0.04825
99.01600,9.46228,-0.04818
99.21600,9.46228,-0.04814
99.41600,9.46228,-0.04808
99.61600,9.46228,-0.04805
99.81600,9.46228,-0.04804
100.01600,9.46228,-0.04795
100.21600,9.46228,-0.04794
100.41600,9.46228,-0.04795
100.61600,9.46228,-0.04788
100.81600,9.46228,-0.04781
101.01600,9.46228,-0.04779
101.21600,9.46228,-0.04774
101.41600,9.46228,-0.04766
101.61600,9.46228,-0.04766
101.81600,9.46228,-0.04759
102.01600,9.46228,-0.04754
102.21600,9.46228,-0.04753
102.41600,9.46228,-0.04748
102.61600,9.46228,-0.04740
102.81600,9.46228,-0.04734
103.01600,9.46228,-0.04731
103.21600,9.46228,-0.04726
103.41600,9.46228,-0.04726
103.61600,9.46228,-0.04719
103.81600,9.46228,-0.04713
104.01600,9.46228,-0.04710
104.21600,9.46228,-0.04701
104.41600,9.46228,-0.04700
104.61600,9.46228,-0.04696
104.81600,9.46228,-0.04693
105.01600,9.46228,-0.04688
105.21600,9.46228,-0.04683
105.41601,9.46228,-0.04677
105.61601,9.46228,-0.04671
105.81601,9.46228,-0.04670
106.01601,9.46228,-0.04664
106.21601,9.46228,-0.04660
106.41601,9.46228,-0.04658
106.61601,9.46228,-0.04652
106.81601,9.46228,-0.04645
107.01601,9.46228,-0.04641
107.21601,9.46228,-0.04638
107.41601,9.46228,-0.04631
107.61601,9.46228,-0.04627
107.81601,9.46228,-0.04625
108.01601,9.46228,-0.04622
108.21601,9.46228,-0.04611
108.41601,9.46228,-0.04613
108.61601,9.46228,-0.04611
108.81601,9.46228,-0.04603
109.01601,9.46228,-0.04602
109.21601,9.46228,-0.04595
109.41601,9.46228,-0.04588
109.61601,9.46228,-0.04587
109.81601,9.46228,-0.04580
110.01601,9.46228,-0.04578
110.21601,9.46228,-0.04572
110.41601,9.46228,-0.04570
110.61601,9.46228,-0.04567
110.81601,9.46228,-0.04560
111.01601,9.46228,-0.04558
111.21601,9.46228,-0.04552
111.41601,9.46228,-0.04550
111.61601,9.46228,-0.04546
111.81601,9.46228,-0.04548
112.01601,9.46228,-0.04540
112.21601,9.46228,-0.04534
112.41601,9.46228,-0.04532
112.61601,9.46228,-0.04526
112.81601,9.46228,-0.04523
113.01601,9.46228,-0.04522
113.21601,9.46228,-0.04515
113.41601,9.46228,-0.04513
113.61601,9.46228,-0.04505
113.81601,9.46228,-0.04507
114.01601,9.46228,-0.04496
114.21601,9.46228,-0.04495
114.41601,9.46228,-0.04493
114.61601,9.46228,-0.04486
114.81601,9.46228,-0.04482
115.01601,9.46228,-0.04481
115.21601,9.46228,-0.04482
115.41601,9.46228,-0.04472
115.61601,9.46228,-0.04472
115.81601,9.46228,-0.04467
116.01601,9.46228,-0.04466
116.21601,9.46228,-0.04464
116.41601,9.46228,-0.04459
116.61601,9.46228,-0.04456
116.81601,9.46228,-0.04451
117.01601,9.46228,-0.04446
117.21601,9.46228,-0.04447
117.41601,9.46228,-0.04442
117.61601,9.46228,-0.04435
117.81601,9.46228,-0.04434
118.01601,9.46228,-0.04431
118.21601,9.46228,-0.04431
118.41601,9.46228,-0.04424
118.61601,9.46228,-0.04423
118.81601,9.46228,-0.04418
119.01601,9.46228,-0.04413
119.21601,9.46228,-0.04412
119.41601,9.46228,-0.04409
119.61601,9.46228,-0.04408
119.81601,9.46228,-0.04407
120.01601,9.46228,-0.04401
120.21601,9.46228,-0.04398
120.41601,9.46228,-0.04392
120.61601,9.46228,-0.04391
120.81601,9.46228,-0.04385
121.01601,9.46228,-0.04382
121.21601,9.46228,-0.04380
121.41601,9.46228,-0.04377
121.61601,9.46228,-0.04372
121.81601,9.46228,-0.04371
122.01601,9.46228,-0.04367
122.21601,9.46228,-0.04367
122.41601,9.46228,-0.04362
122.61601,9.46228,-0.04359
122.81601,9.46228,-0.04354
123.01601,9.46228,-0.04354
123.21601,9.46228,-0.04351
123.41601,9.46228,-0.04346
123.61601,9.46228,-0.04340
123.81601,9.46228,-0.04343
124.01601,9.46228,-0.04339
124.21601,9.46228,-0.04336
124.41601,9.46228,-0.04335
124.61601,9.46228,-0.04332
124.81601,9.46228,-0.04328
125.01601,9.46228,-0.04328
125.21601,9.46228,-0.04324
125.41601,9.46228,-0.04321
125.61601,9.46228,-0.04320
125.81601,9.46228,-0.04316
126.01601,9.46228,-0.04311
126.21601,9.46228,-0.04308
126.41601,9.46228,-0.04302
126.61601,9.46228,-0.04300
126.81601,9.46228,-0.04295
127.01601,9.46228,-0.04289
127.21601,9.46228,-0.04286
127.41601,9.46228,-0.04283
127.61601,9.46228,-0.04281
127.81601,9.46228,-0.04281
128.01601,9.46228,-0.04273
128.21601,9.46228,-0.04271
128.41601,9.46228,-0.04270
128.61601,9.46228,-0.04264
128.81601,9.46228,-0.04262
129.01601,9.46228,-0.04258
129.21601,9.46228,-0.04252
129.41601,9.46228,-0.04256
129.61601,9.46228,-0.04251
129.81601,9.46228,-0.04250
130.01601,9.46228,-0.04245
130.21601,9.46228,-0.04239
130.41601,9.46228,-0.04233
130.61601,9.46228,-0.04233
130.81601,9.46228,-0.04231
131.01601,9.46228,-0.04228
131.21601,9.46228,-0.04222
131.41601,9.46228,-0.04217
131.61601,9.46228,-0.04214
131.81601,9.46228,-0.04212
132.01601,9.46228,-0.04207
132.21601,9.46228,-0.04205
132.41601,9.46228,-0.04196
132.61601,9.46228,-0.04194
132.81601,9.46228,-0.04188
133.01601,9.46228,-0.04186
133.21601,9.46228,-0.04186
133.41601,9.46228,-0.04181
133.61601,9.46228,-0.04180
133.81601,9.46228,-0.04180
134.01601,9.46228,-0.04178
134.21601,9.46228,-0.04171
134.41601,9.46228,-0.04175
134.61601,9.46228,-0.04171
134.81601,9.46228,-0.04165
135.01601,9.46228,-0.04162
135.21601,9.46228,-0.04160
135.41601,9.46228,-0.04155
135.61601,9.46228,-0.04149
135.81601,9.46228,-0.04151
136.01601,9.46228,-0.04146
136.21601,9.46228,-0.04141
136.41601,9.46228,-0.04140
136.61601,9.46228,-0.04135
136.81601,9.46228,-0.04131
137.01601,9.46228,-0.04129
137.21601,9.46228,-0.04125
137.41601,9.46228,-0.04123
137.61601,9.46228,-0.04121
137.81601,9.46228,-0.04118
138.01601,9.46228,-0.04116
138.21601,9.46228,-0.04111
138.41601,9.46228,-0.04109
138.61601,9.46228,-0.04110
138.81601,9.46228,-0.04108
139.01601,9.46228,-0.04103
139.21601,9.46228,-0.04103
139.41601,9.46228,-0.04100
139.61601,9.46228,-0.04095
139.81601,9.46228,-0.04097
140.01601,9.46228,-0.04090
140.21601,9.46228,-0.04085
140.41601,9.46228,-0.04088
140.61601,9.46228,-0.04083
140.81601,9.46228,-0.04082
141.01601,9.46228,-0.04079
141.21601,9.46228,-0.04076
141.41601,9.46228,-0.04074
141.61601,9.46228,-0.04073
141.81601,9.46228,-0.04070
142.01601,9.46228,-0.04062
142.21601,9.46228,-0.04062
142.41601,9.46228,-0.04058
142.61601,9.46228,-0.04056
142.81601,9.46228,-0.04054
143.01601,9.46228,-0.04050
143.21601,9.46228,-0.04048
143.41601,9.46228,-0.04047
143.61601,9.46228,-0.04039
143.81601,9.46228,-0.04036
144.01601,9.46228,-0.04036
144.21601,9.46228,-0.04031
144.41601,9.46228,-0.04028
144.61601,9.46228,-0.04028
144.81601,9.46228,-0.04028
145.01601,9.46228,-0.04024
145.21601,9.46228,-0.04022
145.41601,9.46228,-0.04017
145.61601,9.46228,-0.04012
145.81601,9.46228,-0.04011
146.01601,9.46228,-0.04006
146.21601,9.46228,-0.04004
146.41601,9.46228,-0.04003
146.61601,9.46228,-0.04002
146.81601,9.46228,-0.04000
147.01601,9.46228,-0.03993
147.21601,9.46228,-0.03992
147.41601,9.46228,-0.03990
147.61601,9.46228,-0.03981
147.81601,9.46228,-0.03983
148.01601,9.46228,-0.03978
148.21601,9.46228,-0.03979
148.41601,9.46228,-0.03974
148.61601,9.46228,-0.03970
148.81601,9.46228,-0.03970
149.01601,9.46228,-0.03964
149.21601,9.46228,-0.03965
149.41601,9.46228,-0.03960
149.61601,9.46228,-0.03959
149.81601,9.46228,-0.03954
150.01601,9.46228,-0.03952
150.21601,9.46228,-0.03947
150.41601,9.46228,-0.03945
150.61601,9.46228,-0.03945
150.81601,9.46228,-0.03944
151.01601,9.46228,-0.03938
151.21601,9.46228,-0.03937
151.41601,9.46228,-0.03936
151.61601,9.46228,-0.03930
151.81601,9.46228,-0.03929
152.01601,9.46228,-0.03927
152.21601,9.46228,-0.03926
152.41601,9.46228,-0.03925
152.61601,9.46228,-0.03920
152.81601,9.46228,-0.03919
153.01601,9.46228,-0.03916
153.21601,9.46228,-0.03914
153.41601,9.46228,-0.03910
153.61601,9.46228,-0.03908
153.81601,9.46228,-0.03910
154.01601,9.46228,-0.03905
154.21601,9.46228,-0.03899
154.41601,9.46228,-0.03895
154.61601,9.46228,-0.03898
154.81601,9.46228,-0.03893
155.01601,9.46228,-0.03891
155.21601,9.46228,-0.03890
155.41601,9.46228,-0.03887
155.61601,9.46228,-0.03885
155.81601,9.46228,-0.03883
156.01601,9.46228,-0.03882
156.21601,9.46228,-0.03880
156.41601,9.46228,-0.03876
156.61601,9.46228,-0.03873
156.81601,9.46228,-0.03871
157.01601,9.46228,-0.03868
157.21601,9.46228,-0.03868
157.41601,9.46228,-0.03865
157.61601,9.46228,-0.03859
157.81601,9.46228,-0.03853
158.01601,9.46228,-0.03858
158.21601,9.46228,-0.03854
158.41601,9.46228,-0.03853
158.61601,9.46228,-0.03845
158.81601,9.46228,-0.03849
159.01601,9.46228,-0.03845
159.21601,9.46228,-0.03841
159.41601,9.46228,-0.03842
159.61601,9.46228,-0.03837
159.81601,9.46228,-0.03838
160.01601,9.46228,-0.03834
160.21601,9.46228,-0.03832
160.41601,9.46228,-0.03830
160.61601,9.46228,-0.03830
160.81601,9.46228,-0.03825
161.01601,9.46228,-0.03821
161.21601,9.46228,-0.03823
161.41601,9.46228,-0.03819
161.61601,9.46228,-0.03818
161.81601,9.46228,-0.03814
162.01601,9.46228,-0.03813
162.21601,9.46228,-0.03812
162.41601,9.46228,-0.03807
162.61601,9.46228,-0.03805
162.81601,9.46228,-0.03803
163.01601,9.46228,-0.03802
163.21601,9.46228,-0.03801
163.41601,9.46228,-0.03801
163.61601,9.46228,-0.03796
163.81601,9.46228,-0.03794
164.01601,9.46228,-0.03793
164.21601,9.46228,-0.03789
164.41601,9.46228,-0.03786
164.61601,9.46228,-0.03785
164.81601,9.46228,-0.03786
165.01601,9.46228,-0.03779
165.21601,9.46228,-0.03775
165.41601,9.46228,-0.03775
165.61601,9.46228,-0.03776
165.81601,9.46228,-0.03771
166.01601,9.46228,-0.03774
166.21601,9.46228,-0.03769
166.41601,9.46228,-0.03766
166.61601,9.46228,-0.03766
166.81601,9.46228,-0.03766
167.01601,9.46228,-0.03761
167.21601,9.46228,-0.03762
167.41601,9.46228,-0.03757
167.61601,9.46228,-0.03758
167.81601,9.46228,-0.03755
168.01601,9.46228,-0.03757
168.21601,9.46228,-0.03750
168.41601,9.46228,-0.03749
168.61601,9.46228,-0.03749
168.81601,9.46228,-0.03744
169.01601,9.46228,-0.03745
169.21601,9.46228,-0.03738
169.41601,9.46228,-0.03739
169.61601,9.46228,-0.03738
169.81601,9.46228,-0.03732
170.01601,9.46228,-0.03735
170.21601,9.46228,-0.03731
170.41601,9.46228,-0.03730
170.61601,9.46228,-0.03729
170.81601,9.46228,-0.03728
171.01601,9.46228,-0.03723
171.21601,9.46228,-0.03721
171.41601,9.46228,-0.03719
171.61601,9.46228,-0.03720
171.81601,9.46228,-0.03713
172.01601,9.46228,-0.03714
172.21601,9.46228,-0.03708
172.41601,9.46228,-0.03707
172.61601,9.46228,-0.03707
172.81601,9.46228,-0.03707
173.01601,9.46228,-0.03703
173.21601,9.46228,-0.03704
173.41601,9.46228,-0.03700
173.61601,9.46228,-0.03696
173.81601,9.46228,-0.03701
174.01601,9.46228,-0.03700
174.21601,9.46228,-0.03699
174.41601,9.46228,-0.03692
174.61601,9.46228,-0.03693
174.81601,9.46228,-0.03694
175.01601,9.46228,-0.03687
175.21601,9.46228,-0.03686
175.41601,9.46228,-0.03686
175.61601,9.46228,-0.03683
175.81601,9.46228,-0.03682
176.01601,9.46228,-0.03678
176.21601,9.46228,-0.03677
176.41601,9.46228,-0.03674
176.61601,9.46228,-0.03672
176.81601,9.46228,-0.03673
177.01601,9.46228,-0.03671
177.21601,9.46228,-0.03670
177.41601,9.46228,-0.03667
177.61601,9.46228,-0.03665
177.81601,9.46228,-0.03665
178.01601,9.46228,-0.03664
178.21601,9.46228,-0.03660
178.41601,9.46228,-0.03660
178.61601,9.46228,-0.03659
178.81601,9.46228,-0.03660
179.01601,9.46228,-0.03657
179.21601,9.46228,-0.03654
179.41601,9.46228,-0.03650
179.61601,9.46228,-0.03652
179.81601,9.46228,-0.03647
180.01601,9.46228,-0.03648
180.21601,9.46228,-0.03649
180.41601,9.46228,-0.03647
180.61601,9.46228,-0.03642
180.81601,9.46228,-0.03642
181.01601,9.46228,-0.03636
181.21601,9.46228,-0.03637
181.41601,9.46228,-0.03636
181.61601,9.46228,-0.03634
181.81601,9.46228,-0.03631
182.01601,9.46228,-0.03627
182.21601,9.46228,-0.03627
182.41601,9.46228,-0.03621
182.61601,9.46228,-0.03623
182.81601,9.46228,-0.03622
183.01601,9.46228,-0.03618
183.21601,9.46228,-0.03619
183.41601,9.46228,-0.03616
183.61601,9.46228,-0.03612
183.81601,9.46228,-0.03604
184.01601,9.46228,-0.03609
184.21601,9.46228,-0.03610
184.41601,9.46228,-0.03603
184.61601,9.46228,-0.03606
184.81601,9.46228,-0.03598
185.01601,9.46228,-0.03601
185.21601,9.46228,-0.03599
185.41601,9.46228,-0.03598
185.61601,9.46228,-0.03594
185.81601,9.46228,-0.03591
186.01601,9.46228,-0.03591
186.21601,9.46228,-0.03588
186.41601,9.46228,-0.03586
186.61601,9.46228,-0.03584
186.81601,9.46228,-0.03583
187.01601,9.46228,-0.03582
187.21601,9.46228,-0.03579
187.41601,9.46228,-0.03577
187.61601,9.46228,-0.03571
187.81601,9.46228,-0.03571
188.01601,9.46228,-0.03569
188.21601,9.46228,-0.03570
188.41601,9.46228,-0.03566
188.61601,9.46228,-0.03567
188.81601,9.46228,-0.03561
189.01601,9.46228,-0.03559
189.21601,9.46228,-0.03554
189.41601,9.46228,-0.03556
189.61601,9.46228,-0.03551
189.81601,9.46228,-0.03552
190.01601,9.46228,-0.03546