File: reference/original_matlab_code/ViscoelasticAnalysis/Sample Instron Files/Specimen_RawData_4.csv
Time,Extension,Load
(sec),(mm),(N)
0.00000,9.92186,0.00011
0.20000,9.91977,-0.00007
0.40000,9.90415,-0.00170
0.60000,9.89269,-0.00285
0.80000,9.88228,-0.00399
1.00000,9.87227,-0.00516
1.20000,9.86227,-0.00645
1.40000,9.85207,-0.00780
1.60000,9.84186,-0.00920
1.80000,9.83228,-0.01067
2.00000,9.82227,-0.01224
2.20000,9.81207,-0.01388
2.40000,9.80207,-0.01555
2.60000,9.79207,-0.01730
2.80000,9.78228,-0.01901
3.00000,9.77207,-0.02092
3.20000,9.76165,-0.02291
3.40000,9.75207,-0.02482
3.60000,9.74186,-0.02688
3.80000,9.73186,-0.02891
4.00000,9.72165,-0.03107
4.20000,9.71186,-0.03317
4.40000,9.70227,-0.03528
4.60000,9.69186,-0.03765
4.80000,9.68165,-0.03996
5.00000,9.67207,-0.04226
5.20000,9.66228,-0.04462
5.40000,9.65207,-0.04705
5.60000,9.64207,-0.04966
5.80000,9.63228,-0.05211
6.00000,9.62248,-0.05465
6.20000,9.61186,-0.05748
6.40000,9.60186,-0.06020
6.60000,9.59228,-0.06273
6.80000,9.58248,-0.06546
7.00000,9.57144,-0.06859
7.20000,9.56165,-0.07141
7.40000,9.55207,-0.07414
7.60000,9.54248,-0.07691
7.80000,9.53144,-0.08024
8.00000,9.52165,-0.08318
8.20000,9.51207,-0.08612
8.40000,9.50227,-0.08910
8.60000,9.49207,-0.09229
8.80000,9.48165,-0.09564
9.00000,9.47207,-0.09877
9.20000,9.46228,-0.10197
9.40000,9.45165,-0.10561
9.60000,9.44186,-0.10885
9.80000,9.43228,-0.11200
10.00000,9.42248,-0.11531
10.02200,9.42144,-0.11570
10.22200,9.41998,-0.11531
10.42200,9.41998,-0.11391
10.62200,9.41998,-0.11272
10.82200,9.41998,-0.11169
11.02200,9.41998,-0.11070
11.22200,9.41998,-0.10985
11.42200,9.42040,-0.10898
11.62200,9.42061,-0.10808
11.82200,9.42061,-0.10730
12.02200,9.42082,-0.10650
12.22200,9.42082,-0.10579
12.42200,9.42103,-0.10508
12.62200,9.42103,-0.10433
12.82200,9.42123,-0.10370
13.02200,9.42123,-0.10304
13.22200,9.42123,-0.10244
13.42200,9.42123,-0.10183
13.62200,9.42144,-0.10126
13.82200,9.42144,-0.10072
14.02200,9.42144,-0.10017
14.22200,9.42144,-0.09961
14.42200,9.42144,-0.09914
14.62200,9.42144,-0.09864
14.82200,9.42144,-0.09812
15.02200,9.42144,-0.09760
15.22200,9.42144,-0.09716
15.42200,9.42144,-0.09667
15.62200,9.42144,-0.09620
15.82200,9.42144,-0.09575
16.02200,9.42144,-0.09530
16.22200,9.42144,-0.09486
16.42200,9.42144,-0.09443
16.62200,9.42144,-0.09400
16.82200,9.42144,-0.09358
17.02200,9.42144,-0.09316
17.22200,9.42144,-0.09278
17.42200,9.42144,-0.09237
17.62200,9.42144,-0.09197
17.82200,9.42144,-0.09154
18.02200,9.42144,-0.09116
18.22200,9.42144,-0.09082
18.42200,9.42144,-0.09038
18.62200,9.42144,-0.09007
18.82200,9.42144,-0.08966
19.02200,9.42144,-0.08934
19.22200,9.42144,-0.08896
19.42200,9.42144,-0.08864
19.62200,9.42144,-0.08828
19.82200,9.42144,-0.08797
20.02200,9.42144,-0.08757
20.22200,9.42144,-0.08730
20.42200,9.42144,-0.08696
20.62200,9.42144,-0.08662
20.82200,9.42144,-0.08628
21.02200,9.42144,-0.08595
21.22200,9.42144,-0.08567
21.42200,9.42144,-0.08536
21.62200,9.42144,-0.08503
21.82200,9.42144,-0.08473
22.02200,9.42144,-0.08443
22.22200,9.42144,-0.08411
22.42200,9.42144,-0.08381
22.62200,9.42144,-0.08355
22.82200,9.42144,-0.08325
23.02200,9.42144,-0.08294
23.22200,9.42144,-0.08270
23.42200,9.42144,-0.08242
23.62200,9.42144,-0.08213
23.82200,9.42144,-0.08186
24.02200,9.42144,-0.08159
24.22200,9.42144,-0.08133
24.42200,9.42144,-0.08105
24.62200,9.42144,-0.08082
24.82200,9.42144,-0.08057
25.02200,9.42144,-0.08029
25.22200,9.42144,-0.08004
25.42200,9.42144,-0.07977
25.62200,9.42144,-0.07953
25.82200,9.42144,-0.07929
26.02200,9.42144,-0.07905
26.22200,9.42144,-0.07879
26.42200,9.42144,-0.07856
26.62200,9.42144,-0.07833
26.82200,9.42144,-0.07807
27.02200,9.42144,-0.07780
27.22200,9.42144,-0.07763
27.42200,9.42144,-0.07739
27.62200,9.42144,-0.07714
27.82200,9.42144,-0.07687
28.02200,9.42144,-0.07668
28.22200,9.42144,-0.07648
28.42200,9.42144,-0.07625
28.62200,9.42144,-0.07603
28.82200,9.42144,-0.07580
29.02200,9.42144,-0.07563
29.22200,9.42144,-0.07538
29.42200,9.42144,-0.07516
29.62200,9.42144,-0.07500
29.82200,9.42144,-0.07476
30.02200,9.42144,-0.07451
30.22200,9.42144,-0.07435
30.42200,9.42144,-0.07415
30.62200,9.42144,-0.07396
30.82200,9.42144,-0.07375
31.02200,9.42144,-0.07352
31.22200,9.42144,-0.07333
31.42200,9.42144,-0.07316
31.62200,9.42144,-0.07296
31.82200,9.42144,-0.07275
32.02200,9.42144,-0.07258
32.22200,9.42144,-0.07238
32.42200,9.42144,-0.07219
32.62200,9.42144,-0.07199
32.82200,9.42144,-0.07184
33.02200,9.42144,-0.07167
33.22200,9.42144,-0.07144
33.42200,9.42144,-0.07129
33.62200,9.42144,-0.07114
33.82200,9.42144,-0.07090
34.02200,9.42144,-0.07075
34.22200,9.42144,-0.07057
34.42200,9.42144,-0.07041
34.62200,9.42144,-0.07025
34.82200,9.42144,-0.07009
35.02200,9.42144,-0.06991
35.22200,9.42144,-0.06971
35.42200,9.42144,-0.06957
35.62200,9.42144,-0.06941
35.82200,9.42144,-0.06919
36.02200,9.42144,-0.06904
36.22200,9.42144,-0.06891
36.42200,9.42144,-0.06873
36.62200,9.42144,-0.06859
36.82200,9.42144,-0.06842
37.02200,9.42144,-0.06828
37.22200,9.42144,-0.06814
37.42200,9.42144,-0.06798
37.62200,9.42144,-0.06780
37.82200,9.42144,-0.06762
38.02200,9.42144,-0.06747
38.22200,9.42144,-0.06731
38.42200,9.42144,-0.06716
38.62200,9.42144,-0.06702
38.82200,9.42144,-0.06685
39.02200,9.42144,-0.06670
39.22200,9.42144,-0.06651
39.42200,9.42144,-0.06639
39.62200,9.42144,-0.06625
39.82200,9.42144,-0.06608
40.02200,9.42144,-0.06593
40.22200,9.42144,-0.06583
40.42200,9.42144,-0.06568
40.62200,9.42144,-0.06553
40.82200,9.42144,-0.06539
41.02200,9.42144,-0.06523
41.22200,9.42144,-0.06508
41.42200,9.42144,-0.06494
41.62200,9.42144,-0.06483
41.82200,9.42144,-0.06469
42.02200,9.42144,-0.06453
42.22200,9.42144,-0.06440
42.42200,9.42144,-0.06428
42.62200,9.42144,-0.06414
42.82200,9.42144,-0.06402
43.02200,9.42144,-0.06391
43.22200,9.42144,-0.06373
43.42200,9.42144,-0.06362
43.62200,9.42144,-0.06349
43.82200,9.42144,-0.06336
44.02200,9.42144,-0.06320
44.22200,9.42144,-0.06310
44.42200,9.42144,-0.06295
44.62200,9.42144,-0.06285
44.82200,9.42144,-0.06271
45.02200,9.42144,-0.06256
45.22200,9.42144,-0.06241
45.42200,9.42144,-0.06237
45.62200,9.42144,-0.06224
45.82200,9.42144,-0.06209
46.02200,9.42144,-0.06198
46.22200,9.42144,-0.06188
46.42200,9.42144,-0.06173
46.62200,9.42144,-0.06162
46.82200,9.42144,-0.06148
47.02200,9.42144,-0.06140
47.22200,9.42144,-0.06128
47.42200,9.42144,-0.06114
47.62200,9.42144,-0.06105
47.82200,9.42144,-0.06094
48.02200,9.42144,-0.06080
48.22200,9.42144,-0.06070
48.42200,9.42144,-0.06057
48.62200,9.42144,-0.06043
48.82200,9.42144,-0.06036
49.02200,9.42144,-0.06023
49.22200,9.42144,-0.06015
49.42200,9.42144,-0.06003
49.62200,9.42144,-0.05990
49.82200,9.42144,-0.05980
50.02200,9.42144,-0.05970
50.22200,9.42144,-0.05958
50.42200,9.42144,-0.05946
50.62200,9.42144,-0.05937
50.82200,9.42144,-0.05928
51.02200,9.42144,-0.05911
51.22200,9.42144,-0.05903
51.42200,9.42144,-0.05894
51.62200,9.42144,-0.05878
51.82200,9.42144,-0.05871
52.02200,9.42144,-0.05860
52.22200,9.42144,-0.05850
52.42200,9.42144,-0.05839
52.62200,9.42144,-0.05828
52.82200,9.42144,-0.05821
53.02200,9.42144,-0.05808
53.22200,9.42144,-0.05797
53.42200,9.42144,-0.05788
53.62200,9.42144,-0.05779
53.82200,9.42144,-0.05768
54.02200,9.42144,-0.05757
54.22200,9.42144,-0.05745
54.42200,9.42144,-0.05740
54.62200,9.42144,-0.05728
54.82200,9.42144,-0.05718
55.02200,9.42144,-0.05709
55.22200,9.42144,-0.05695
55.42200,9.42144,-0.05690
55.62200,9.42144,-0.05682
55.82200,9.42144,-0.05670
56.02200,9.42144,-0.05657
56.22200,9.42144,-0.05649
56.42200,9.42144,-0.05642
56.62200,9.42144,-0.05632
56.82200,9.42144,-0.05624
57.02200,9.42144,-0.05615
57.22200,9.42144,-0.05603
57.42200,9.42144,-0.05600
57.62200,9.42144,-0.05584
57.82200,9.42144,-0.05580
58.02200,9.42144,-0.05569
58.22200,9.42144,-0.05560
58.42200,9.42144,-0.05548
58.62200,9.42144,-0.05540
58.82200,9.42144,-0.05533
59.02200,9.42144,-0.05521
59.22200,9.42144,-0.05516
59.42200,9.42144,-0.05507
59.62200,9.42144,-0.05494
59.82200,9.42144,-0.05485
60.02200,9.42144,-0.05480
60.22200,9.42144,-0.05473
60.42200,9.42144,-0.05462
60.62200,9.42144,-0.05451
60.82200,9.42144,-0.05448
61.02200,9.42144,-0.05436
61.22200,9.42144,-0.05431
61.42200,9.42144,-0.05421
61.62200,9.42144,-0.05414
61.82200,9.42144,-0.05405
62.02200,9.42144,-0.05395
62.22200,9.42144,-0.05386
62.42200,9.42144,-0.05375
62.62200,9.42144,-0.05371
62.82200,9.42144,-0.05360
63.02200,9.42144,-0.05354
63.22200,9.42144,-0.05343
63.42200,9.42144,-0.05335
63.62200,9.42144,-0.05323
63.82200,9.42144,-0.05321
64.02200,9.42144,-0.05309
64.22200,9.42144,-0.05304
64.42200,9.42144,-0.05295
64.62200,9.42144,-0.05285
64.82200,9.42144,-0.05281
65.02200,9.42144,-0.05270
65.22200,9.42144,-0.05263
65.42200,9.42144,-0.05256
65.62200,9.42144,-0.05244
65.82200,9.42144,-0.05238
66.02200,9.42144,-0.05232
66.22200,9.42144,-0.05224
66.42200,9.42144,-0.05212
66.62200,9.42144,-0.05206
66.82200,9.42144,-0.05202
67.02200,9.42144,-0.05195
67.22200,9.42144,-0.05187
67.42200,9.42144,-0.05180
67.62200,9.42144,-0.05171
67.82200,9.42144,-0.05163
68.02200,9.42144,-0.05155
68.22200,9.42144,-0.05154
68.42200,9.42144,-0.05143
68.62200,9.42144,-0.05137
68.82200,9.42144,-0.05128
69.02200,9.42144,-0.05121
69.22200,9.42144,-0.05117
69.42200,9.42144,-0.05111
69.62200,9.42144,-0.05101
69.82200,9.42144,-0.05094
70.02200,9.42144,-0.05087
70.22200,9.42144,-0.05080
70.42200,9.42144,-0.05071
70.62200,9.42144,-0.05063
70.82200,9.42144,-0.05060
71.02200,9.42144,-0.05053
71.22200,9.42144,-0.05047
71.42200,9.42144,-0.05038
71.62200,9.42144,-0.05028
71.82200,9.42144,-0.05024
72.02200,9.42144,-0.05015
72.22200,9.42144,-0.05010
72.42200,9.42144,-0.05002
72.62200,9.42144,-0.04995
72.82200,9.42144,-0.04990
73.02200,9.42144,-0.04981
73.22200,9.42144,-0.04977
73.42200,9.42144,-0.04967
73.62200,9.42144,-0.04963
73.82200,9.42144,-0.04956
74.02200,9.42144,-0.04945
74.22200,9.42144,-0.04944
74.42200,9.42144,-0.04934
74.62200,9.42144,-0.04930
74.82200,9.42144,-0.04922
75.02200,9.42144,-0.04915
75.22200,9.42144,-0.04911
75.42200,9.42144,-0.04901
75.62200,9.42144,-0.04896
75.82200,9.42144,-0.04889
76.02200,9.42144,-0.04883
76.22200,9.42144,-0.04876
76.42200,9.42144,-0.04871
76.62200,9.42144,-0.04864
76.82200,9.42144,-0.04861
77.02200,9.42144,-0.04854
77.22200,9.42144,-0.04848
77.42200,9.42144,-0.04843
77.62200,9.42144,-0.04837
77.82200,9.42144,-0.04828
78.02200,9.42144,-0.04825
78.22200,9.42144,-0.04820
78.42200,9.42144,-0.04817
78.62200,9.42144,-0.04809
78.82200,9.42144,-0.04805
79.02200,9.42144,-0.04801
79.22200,9.42144,-0.04796
79.42200,9.42144,-0.04786
79.62200,9.42144,-0.04782
79.82200,9.42144,-0.04773
80.02200,9.42144,-0.04771
80.22200,9.42144,-0.04768
80.42200,9.42144,-0.04759
80.62200,9.42144,-0.04750
80.82200,9.42144,-0.04748
81.02200,9.42144,-0.04744
81.22200,9.42144,-0.04736
81.42200,9.42144,-0.04728
81.62200,9.42144,-0.04727
81.82200,9.42144,-0.04720
82.02200,9.42144,-0.04712
82.22200,9.42144,-0.04709
82.42200,9.42144,-0.04703
82.62200,9.42144,-0.04699
82.82200,9.42144,-0.04693
83.02200,9.42144,-0.04688
83.22200,9.42144,-0.04683
83.42200,9.42144,-0.04680
83.62200,9.42144,-0.04673
83.82200,9.42144,-0.04665
84.02200,9.42144,-0.04661
84.22200,9.42144,-0.04655
84.42200,9.42144,-0.04648
84.62200,9.42144,-0.04644
84.82200,9.42144,-0.04641
85.02200,9.42144,-0.04631
85.22200,9.42144,-0.04627
85.42200,9.42144,-0.04622
85.62200,9.42144,-0.04619
85.82200,9.42144,-0.04610
86.02200,9.42144,-0.04608
86.22200,9.42144,-0.04602
86.42200,9.42144,-0.04596
86.62200,9.42144,-0.04594
86.82200,9.42144,-0.04588
87.02200,9.42144,-0.04582
87.22200,9.42144,-0.04579
87.42200,9.42144,-0.04579
87.62200,9.42144,-0.04569
87.82200,9.42144,-0.04566
88.02200,9.42144,-0.04560
88.22200,9.42144,-0.04556
88.42200,9.42144,-0.04551
88.62200,9.42144,-0.04546
88.82200,9.42144,-0.04543
89.02200,9.42144,-0.04533
89.22200,9.42144,-0.04532
89.42200,9.42144,-0.04527
89.62200,9.42144,-0.04523
89.82200,9.42144,-0.04515
90.02200,9.42144,-0.04511
90.22200,9.42144,-0.04503
90.42200,9.42144,-0.04500
90.62200,9.42144,-0.04493
90.82200,9.42144,-0.04486
91.02200,9.42144,-0.04489
91.22200,9.42144,-0.04480
91.42200,9.42144,-0.04478
91.62200,9.42144,-0.04472
91.82200,9.42144,-0.04467
92.02200,9.42144,-0.04462
92.22200,9.42144,-0.04454
92.42200,9.42144,-0.04459
92.62200,9.42144,-0.04454
92.82200,9.42144,-0.04444
93.02200,9.42144,-0.04437
93.22200,9.42144,-0.04435
93.42200,9.42144,-0.04430
93.62200,9.42144,-0.04427
93.82200,9.42144,-0.04420
94.02200,9.42144,-0.04419
94.22200,9.42144,-0.04411
94.42200,9.42144,-0.04412
94.62200,9.42144,-0.04405
94.82200,9.42144,-0.04402
95.02200,9.42144,-0.04396
95.22200,9.42144,-0.04393
95.42200,9.42144,-0.04386
95.62200,9.42144,-0.04385
95.82200,9.42144,-0.04377
96.02200,9.42144,-0.04371
96.22200,9.42144,-0.04367
96.42200,9.42144,-0.04366
96.62200,9.42144,-0.04356
96.82200,9.42144,-0.04351
97.02200,9.42144,-0.04351
97.22200,9.42144,-0.04346
97.42200,9.42144,-0.04343
97.62200,9.42144,-0.04337
97.82200,9.42144,-0.04335
98.02200,9.42144,-0.04329
98.22200,9.42144,-0.04329
98.42200,9.42144,-0.04322
98.62200,9.42144,-0.04318
98.82200,9.42144,-0.04315
99.02200,9.42144,-0.04312
99.22200,9.42144,-0.04304
99.42200,9.42144,-0.04301
99.62200,9.42144,-0.04297
99.82200,9.42144,-0.04293
100.02200,9.42144,-0.04288
100.22200,9.42144,-0.04286
100.42200,9.42144,-0.04280
100.62200,9.42144,-0.04278
100.82200,9.42144,-0.04271
101.02200,9.42144,-0.04267
101.22200,9.42144,-0.04263
101.42200,9.42144,-0.04260
101.62200,9.42144,-0.04257
101.82200,9.42144,-0.04250
102.02200,9.42144,-0.04248
102.22200,9.42144,-0.04244
102.42200,9.42144,-0.04236
102.62200,9.42144,-0.04234
102.82200,9.42144,-0.04230
103.02200,9.42144,-0.04227
103.22200,9.42144,-0.04221
103.42200,9.42144,-0.04218
103.62200,9.42144,-0.04215
103.82200,9.42144,-0.04207
104.02200,9.42144,-0.04203
104.22200,9.42144,-0.04202
104.42200,9.42144,-0.04197
104.62200,9.42144,-0.04194
104.82200,9.42144,-0.04192
105.02200,9.42144,-0.04183
105.22200,9.42144,-0.04183
105.42201,9.42144,-0.04180
105.62201,9.42144,-0.04176
105.82201,9.42144,-0.04169
106.02201,9.42144,-0.04168
106.22201,9.42144,-0.04165
106.42201,9.42144,-0.04161
106.62201,9.42144,-0.04157
106.82201,9.42144,-0.04153
107.02201,9.42144,-0.04149
107.22201,9.42144,-0.04146
107.42201,9.42144,-0.04142
107.62201,9.42144,-0.04138
107.82201,9.42144,-0.04135
108.02201,9.42144,-0.04131
108.22201,9.42144,-0.04128
108.42201,9.42144,-0.04122
108.62201,9.42144,-0.04121
108.82201,9.42144,-0.04119
109.02201,9.42144,-0.04115
109.22201,9.42144,-0.04111
109.42201,9.42144,-0.04111
109.62201,9.42144,-0.04108
109.82201,9.42144,-0.04103
110.02201,9.42144,-0.04099
110.22201,9.42144,-0.04096
110.42201,9.42144,-0.04091
110.62201,9.42144,-0.04087
110.82201,9.42144,-0.04086
111.02201,9.42144,-0.04081
111.22201,9.42144,-0.04076
111.42201,9.42144,-0.04076
111.62201,9.42144,-0.04071
111.82201,9.42144,-0.04067
112.02201,9.42144,-0.04060
112.22201,9.42144,-0.04060
112.42201,9.42144,-0.04054
112.62201,9.42144,-0.04052
112.82201,9.42144,-0.04052
113.02201,9.42144,-0.04048
113.22201,9.42144,-0.04045
113.42201,9.42144,-0.04041
113.62201,9.42144,-0.04033
113.82201,9.42144,-0.04035
114.02201,9.42144,-0.04028
114.22201,9.42144,-0.04024
114.42201,9.42144,-0.04020
114.62201,9.42144,-0.04022
114.82201,9.42144,-0.04018
115.02201,9.42144,-0.04011
115.22201,9.42144,-0.04006
115.42201,9.42144,-0.04005
115.62201,9.42144,-0.03998
115.82201,9.42144,-0.03998
116.02201,9.42144,-0.03998
116.22201,9.42144,-0.03993
116.42201,9.42144,-0.03987
116.62201,9.42144,-0.03986
116.82201,9.42144,-0.03981
117.02201,9.42144,-0.03976
117.22201,9.42144,-0.03971
117.42201,9.42144,-0.03973
117.62201,9.42144,-0.03969
117.82201,9.42144,-0.03965
118.02201,9.42144,-0.03963
118.22201,9.42144,-0.03960
118.42201,9.42144,-0.03955
118.62201,9.42144,-0.03951
118.82201,9.42144,-0.03948
119.02201,9.42144,-0.03944
119.22201,9.42144,-0.03940
119.42201,9.42144,-0.03939
119.62201,9.42144,-0.03938
119.82201,9.42144,-0.03931
120.02201,9.42144,-0.03931
120.22201,9.42144,-0.03925
120.42201,9.42144,-0.03927
120.62201,9.42144,-0.03916
120.82201,9.42144,-0.03913
121.02201,9.42144,-0.03912
121.22201,9.42144,-0.03909
121.42201,9.42144,-0.03905
121.62201,9.42144,-0.03902
121.82201,9.42144,-0.03900
122.02201,9.42144,-0.03899
122.22201,9.42144,-0.03893
122.42201,9.42144,-0.03890
122.62201,9.42144,-0.03893
122.82201,9.42144,-0.03887
123.02201,9.42144,-0.03885
123.22201,9.42144,-0.03879
123.42201,9.42144,-0.03879
123.62201,9.42144,-0.03877
123.82201,9.42144,-0.03872
124.02201,9.42144,-0.03872
124.22201,9.42144,-0.03868
124.42201,9.42144,-0.03863
124.62201,9.42144,-0.03857
124.82201,9.42144,-0.03857
125.02201,9.42144,-0.03854
125.22201,9.42144,-0.03850
125.42201,9.42144,-0.03848
125.62201,9.42144,-0.03844
125.82201,9.42144,-0.03841
126.02201,9.42144,-0.03837
126.22201,9.42144,-0.03834
126.42201,9.42144,-0.03833
126.62201,9.42144,-0.03829
126.82201,9.42144,-0.03826
127.02201,9.42144,-0.03822
127.22201,9.42144,-0.03821
127.42201,9.42144,-0.03816
127.62201,9.42144,-0.03817
127.82201,9.42144,-0.03810
128.02201,9.42144,-0.03809
128.22201,9.42144,-0.03807
128.42201,9.42144,-0.03806
128.62201,9.42144,-0.03801
128.82201,9.42144,-0.03799
129.02201,9.42144,-0.03797
129.22201,9.42144,-0.03793
129.42201,9.42144,-0.03790
129.62201,9.42144,-0.03790
129.82201,9.42144,-0.03788
130.02201,9.42144,-0.03783
130.22201,9.42144,-0.03781
130.42201,9.42144,-0.03779
130.62201,9.42144,-0.03776
130.82201,9.42144,-0.03768
131.02201,9.42144,-0.03772
131.22201,9.42144,-0.03766
131.42201,9.42144,-0.03762
131.62201,9.42144,-0.03761
131.82201,9.42144,-0.03757
132.02201,9.42144,-0.03756
132.22201,9.42144,-0.03756
132.42201,9.42144,-0.03750
132.62201,9.42144,-0.03748
132.82201,9.42144,-0.03744
133.02201,9.42144,-0.03742
133.22201,9.42144,-0.03742
133.42201,9.42144,-0.03735
133.62201,9.42144,-0.03736
133.82201,9.42144,-0.03735
134.02201,9.42144,-0.03731
134.22201,9.42144,-0.03729
134.42201,9.42144,-0.03729
134.62201,9.42144,-0.03722
134.82201,9.42144,-0.03721
135.02201,9.42144,-0.03721
135.22201,9.42144,-0.03716
135.42201,9.42144,-0.03712
135.62201,9.42144,-0.03708
135.82201,9.42144,-0.03707
136.02201,9.42144,-0.03704
136.22201,9.42144,-0.03702
136.42201,9.42144,-0.03701
136.62201,9.42144,-0.03695
136.82201,9.42144,-0.03694
137.02201,9.42144,-0.03693
137.22201,9.42144,-0.03689
137.42201,9.42144,-0.03684
137.62201,9.42144,-0.03685
137.82201,9.42144,-0.03683
138.02201,9.42144,-0.03681
138.22201,9.42144,-0.03678
138.42201,9.42144,-0.03676
138.62201,9.42144,-0.03674
138.82201,9.42144,-0.03669
139.02201,9.42144,-0.03668
139.22201,9.42144,-0.03666
139.42201,9.42144,-0.03665
139.62201,9.42144,-0.03659
139.82201,9.42144,-0.03658
140.02201,9.42144,-0.03655
140.22201,9.42144,-0.03654
140.42201,9.42144,-0.03654
140.62201,9.42144,-0.03647
140.82201,9.42144,-0.03648
141.02201,9.42144,-0.03646
141.22201,9.42144,-0.03641
141.42201,9.42144,-0.03641
141.62201,9.42144,-0.03635
141.82201,9.42144,-0.03633
142.02201,9.42144,-0.03632
142.22201,9.42144,-0.03631
142.42201,9.42144,-0.03625
142.62201,9.42144,-0.03624
142.82201,9.42144,-0.03623
143.02201,9.42144,-0.03620
143.22201,9.42144,-0.03616
143.42201,9.42144,-0.03617
143.62201,9.42144,-0.03613
143.82201,9.42144,-0.03610
144.02201,9.42144,-0.03604
144.22201,9.42144,-0.03609
144.42201,9.42144,-0.03603
144.62201,9.42144,-0.03600
144.82201,9.42144,-0.03598
145.02201,9.42144,-0.03600
145.22201,9.42144,-0.03592
145.42201,9.42144,-0.03595
145.62201,9.42144,-0.03590
145.82201,9.42144,-0.03585
146.02201,9.42144,-0.03584
146.22201,9.42144,-0.03579
146.42201,9.42144,-0.03578
146.62201,9.42144,-0.03575
146.82201,9.42144,-0.03575
147.02201,9.42144,-0.03573
147.22201,9.42144,-0.03570
147.42201,9.42144,-0.03564
147.62201,9.42144,-0.03564
147.82201,9.42144,-0.03565
148.02201,9.42144,-0.03564
148.22201,9.42144,-0.03556
148.42201,9.42144,-0.03556
148.62201,9.42144,-0.03553
148.82201,9.42144,-0.03553
149.02201,9.42144,-0.03549
149.22201,9.42144,-0.03549
149.42201,9.42144,-0.03545
149.62201,9.42144,-0.03541
149.82201,9.42144,-0.03542
150.02201,9.42144,-0.03541
150.22201,9.42144,-0.03537
150.42201,9.42144,-0.03538
150.62201,9.42144,-0.03533
150.82201,9.42144,-0.03530
151.02201,9.42144,-0.03529
151.22201,9.42144,-0.03530
151.42201,9.42144,-0.03525
151.62201,9.42144,-0.03521
151.82201,9.42144,-0.03523
152.02201,9.42144,-0.03518
152.22201,9.42144,-0.03519
152.42201,9.42144,-0.03512
152.62201,9.42144,-0.03510
152.82201,9.42144,-0.03512
153.02201,9.42144,-0.03510
153.22201,9.42144,-0.03507
153.42201,9.42144,-0.03504
153.62201,9.42144,-0.03503
153.82201,9.42144,-0.03499
154.02201,9.42144,-0.03500
154.22201,9.42144,-0.03498
154.42201,9.42144,-0.03496
154.62201,9.42144,-0.03495
154.82201,9.42144,-0.03490
155.02201,9.42144,-0.03488
155.22201,9.42144,-0.03487
155.42201,9.42144,-0.03485
155.62201,9.42144,-0.03485
155.82201,9.42144,-0.03480
156.02201,9.42144,-0.03481
156.22201,9.42144,-0.03477
156.42201,9.42144,-0.03474
156.62201,9.42144,-0.03475
156.82201,9.42144,-0.03472
157.02201,9.42144,-0.03469
157.22201,9.42144,-0.03472
157.42201,9.42144,-0.03466
157.62201,9.42144,-0.03465
157.82201,9.42144,-0.03463
158.02201,9.42144,-0.03461
158.22201,9.42144,-0.03460
158.42201,9.42144,-0.03455
158.62201,9.42144,-0.03456
158.82201,9.42144,-0.03452
159.02201,9.42144,-0.03451
159.22201,9.42144,-0.03451
159.42201,9.42144,-0.03447
159.62201,9.42144,-0.03444
159.82201,9.42144,-0.03442
160.02201,9.42144,-0.03444
160.22201,9.42144,-0.03438
160.42201,9.42144,-0.03440
160.62201,9.42144,-0.03437
160.82201,9.42144,-0.03434
161.02201,9.42144,-0.03438
161.22201,9.42144,-0.03431
161.42201,9.42144,-0.03430
161.62201,9.42144,-0.03428
161.82201,9.42144,-0.03428
162.02201,9.42144,-0.03424
162.22201,9.42144,-0.03423
162.42201,9.42144,-0.03423
162.62201,9.42144,-0.03417
162.82201,9.42144,-0.03418
163.02201,9.42144,-0.03417
163.22201,9.42144,-0.03416
163.42201,9.42144,-0.03411
163.62201,9.42144,-0.03411
163.82201,9.42144,-0.03407
164.02201,9.42144,-0.03404
164.22201,9.42144,-0.03406
164.42201,9.42144,-0.03402
164.62201,9.42144,-0.03401
164.82201,9.42144,-0.03396
165.02201,9.42144,-0.03397
165.22201,9.42144,-0.03398
165.42201,9.42144,-0.03394
165.62201,9.42144,-0.03394
165.82201,9.42144,-0.03393
166.02201,9.42144,-0.03388
166.22201,9.42144,-0.03386
166.42201,9.42144,-0.03389
166.62201,9.42144,-0.03385
166.82201,9.42144,-0.03383
167.02201,9.42144,-0.03383
167.22201,9.42144,-0.03379
167.42201,9.42144,-0.03378
167.62201,9.42144,-0.03374
167.82201,9.42144,-0.03372
168.02201,9.42144,-0.03369
168.22201,9.42144,-0.03369
168.42201,9.42144,-0.03365
168.62201,9.42144,-0.03362
168.82201,9.42144,-0.03365
169.02201,9.42144,-0.03363
169.22201,9.42144,-0.03360
169.42201,9.42144,-0.03363
169.62201,9.42144,-0.03358
169.82201,9.42144,-0.03359
170.02201,9.42144,-0.03354
170.22201,9.42144,-0.03356
170.42201,9.42144,-0.03352
170.62201,9.42144,-0.03356
170.82201,9.42144,-0.03351
171.02201,9.42144,-0.03346
171.22201,9.42144,-0.03344
171.42201,9.42144,-0.03346
171.62201,9.42144,-0.03344
171.82201,9.42144,-0.03343
172.02201,9.42144,-0.03343
172.22201,9.42144,-0.03339
172.42201,9.42144,-0.03340
172.62201,9.42144,-0.03339
172.82201,9.42144,-0.03335
173.02201,9.42144,-0.03335
173.22201,9.42144,-0.03332
173.42201,9.42144,-0.03333
173.62201,9.42144,-0.03331
173.82201,9.42144,-0.03330
174.02201,9.42144,-0.03330
174.22201,9.42144,-0.03326
174.42201,9.42144,-0.03326
174.62201,9.42144,-0.03323
174.82201,9.42144,-0.03323
175.02201,9.42144,-0.03322
175.22201,9.42144,-0.03324
175.42201,9.42144,-0.03318
175.62201,9.42144,-0.03313
175.82201,9.42144,-0.03314
176.02201,9.42144,-0.03314
176.22201,9.42144,-0.03309
176.42201,9.42144,-0.03307
176.62201,9.42144,-0.03303
176.82201,9.42144,-0.03304
177.02201,9.42144,-0.03302
177.22201,9.42144,-0.03303
177.42201,9.42144,-0.03299
177.62201,9.42144,-0.03298
177.82201,9.42144,-0.03296
178.02201,9.42144,-0.03298
178.22201,9.42144,-0.03293
178.42201,9.42144,-0.03289
178.62201,9.42144,-0.03292
178.82201,9.42144,-0.03289
179.02201,9.42144,-0.03288
179.22201,9.42144,-0.03289
179.42201,9.42144,-0.03283
179.62201,9.42144,-0.03277
179.82201,9.42144,-0.03281
180.02201,9.42144,-0.03281
180.22201,9.42144,-0.03279
180.42201,9.42144,-0.03278
180.62201,9.42144,-0.03275
180.82201,9.42144,-0.03275
181.02201,9.42144,-0.03272
181.22201,9.42144,-0.03268
181.42201,9.42144,-0.03268
181.62201,9.42144,-0.03267
181.82201,9.42144,-0.03264
182.02201,9.42144,-0.03267
182.22201,9.42144,-0.03266
182.42201,9.42144,-0.03260
182.62201,9.42144,-0.03262
182.82201,9.42144,-0.03258
183.02201,9.42144,-0.03257
183.22201,9.42144,-0.03254
183.42201,9.42144,-0.03255
183.62201,9.42144,-0.03249
183.82201,9.42144,-0.03251
184.02201,9.42144,-0.03248
184.22201,9.42144,-0.03247
184.42201,9.42144,-0.03249
184.62201,9.42144,-0.03246
184.82201,9.42144,-0.03245
185.02201,9.42144,-0.03240
185.22201,9.42144,-0.03237
185.42201,9.42144,-0.03239
185.62201,9.42144,-0.03234
185.82201,9.42144,-0.03232
186.02201,9.42144,-0.03232
186.22201,9.42144,-0.03232
186.42201,9.42144,-0.03225
186.62201,9.42144,-0.03229
186.82201,9.42144,-0.03227
187.02201,9.42144,-0.03225
187.22201,9.42144,-0.03221
187.42201,9.42144,-0.03221
187.62201,9.42144,-0.03222
187.82201,9.42144,-0.03217
188.02201,9.42144,-0.03217
188.22201,9.42144,-0.03221
188.42201,9.42144,-0.03217
188.62201,9.42144,-0.03214
188.82201,9.42144,-0.03215
189.02201,9.42144,-0.03211
189.22201,9.42144,-0.03211
189.42201,9.42144,-0.03208
189.62201,9.42144,-0.03209
189.82201,9.42144,-0.03208
190.02201,9.42144,-0.03207