File: reference/original_matlab_code/ViscoelasticAnalysis/Sample Instron Files/Specimen_RawData_3.csv
Time,Extension,Load
(sec),(mm),(N)
0.00000,9.97769,0.00007
0.20000,9.97519,-0.00011
0.40000,9.95957,-0.00157
0.60000,9.94852,-0.00263
0.80000,9.93894,-0.00360
1.00000,9.92811,-0.00482
1.20000,9.91769,-0.00615
1.40000,9.90790,-0.00744
1.60000,9.89852,-0.00873
1.80000,9.88811,-0.01035
2.00000,9.87811,-0.01198
2.20000,9.86832,-0.01365
2.40000,9.85852,-0.01541
2.60000,9.84811,-0.01739
2.80000,9.83811,-0.01934
3.00000,9.82852,-0.02126
3.20000,9.81853,-0.02336
3.40000,9.80832,-0.02567
3.60000,9.79811,-0.02793
3.80000,9.78832,-0.03024
4.00000,9.77832,-0.03259
4.20000,9.76811,-0.03509
4.40000,9.75748,-0.03777
4.60000,9.74811,-0.04017
4.80000,9.73790,-0.04284
5.00000,9.72790,-0.04560
5.20000,9.71769,-0.04836
5.40000,9.70811,-0.05104
5.60000,9.69853,-0.05371
5.80000,9.68811,-0.05679
6.00000,9.67790,-0.05986
6.20000,9.66832,-0.06271
6.40000,9.65832,-0.06561
6.60000,9.64790,-0.06892
6.80000,9.63811,-0.07199
7.00000,9.62832,-0.07508
7.20000,9.61832,-0.07832
7.40000,9.60790,-0.08182
7.60000,9.59811,-0.08499
7.80000,9.58832,-0.08825
8.00000,9.57811,-0.09169
8.20000,9.56748,-0.09553
8.40000,9.55790,-0.09882
8.60000,9.54832,-0.10207
8.80000,9.53832,-0.10549
9.00000,9.52748,-0.10958
9.20000,9.51790,-0.11299
9.40000,9.50811,-0.11641
9.60000,9.49832,-0.11999
9.80000,9.48790,-0.12388
10.00000,9.47811,-0.12748
10.00800,9.47769,-0.12762
10.20800,9.47603,-0.12694
10.40800,9.47603,-0.12493
10.60800,9.47603,-0.12324
10.80800,9.47603,-0.12182
11.00800,9.47603,-0.12050
11.20800,9.47644,-0.11921
11.40800,9.47644,-0.11801
11.60800,9.47665,-0.11676
11.80800,9.47686,-0.11564
12.00800,9.47707,-0.11450
12.20800,9.47707,-0.11340
12.40800,9.47728,-0.11240
12.60800,9.47728,-0.11148
12.80800,9.47748,-0.11053
13.00800,9.47748,-0.10969
13.20800,9.47748,-0.10880
13.40800,9.47769,-0.10807
13.60800,9.47769,-0.10731
13.80800,9.47769,-0.10656
14.00800,9.47769,-0.10585
14.20800,9.47769,-0.10516
14.40800,9.47769,-0.10448
14.60800,9.47769,-0.10384
14.80800,9.47769,-0.10319
15.00800,9.47769,-0.10254
15.20800,9.47769,-0.10198
15.40800,9.47769,-0.10137
15.60800,9.47769,-0.10076
15.80800,9.47769,-0.10022
16.00800,9.47769,-0.09967
16.20800,9.47769,-0.09912
16.40800,9.47769,-0.09855
16.60800,9.47769,-0.09804
16.80800,9.47769,-0.09750
17.00800,9.47769,-0.09701
17.20800,9.47769,-0.09651
17.40800,9.47769,-0.09605
17.60800,9.47769,-0.09552
17.80800,9.47769,-0.09505
18.00800,9.47769,-0.09457
18.20800,9.47769,-0.09411
18.40800,9.47769,-0.09367
18.60800,9.47769,-0.09326
18.80800,9.47769,-0.09282
19.00800,9.47769,-0.09238
19.20800,9.47769,-0.09197
19.40800,9.47769,-0.09155
19.60800,9.47769,-0.09113
19.80800,9.47769,-0.09071
20.00800,9.47769,-0.09034
20.20800,9.47769,-0.08995
20.40800,9.47769,-0.08958
20.60800,9.47769,-0.08918
20.80800,9.47769,-0.08878
21.00800,9.47769,-0.08843
21.20800,9.47769,-0.08803
21.40800,9.47769,-0.08771
21.60800,9.47769,-0.08733
21.80800,9.47769,-0.08698
22.00800,9.47769,-0.08666
22.20800,9.47769,-0.08628
22.40800,9.47769,-0.08594
22.60800,9.47769,-0.08566
22.80800,9.47769,-0.08530
23.00800,9.47769,-0.08497
23.20800,9.47769,-0.08468
23.40800,9.47769,-0.08435
23.60800,9.47769,-0.08402
23.80800,9.47769,-0.08372
24.00800,9.47769,-0.08340
24.20800,9.47769,-0.08313
24.40800,9.47769,-0.08281
24.60800,9.47769,-0.08250
24.80800,9.47769,-0.08220
25.00800,9.47769,-0.08196
25.20800,9.47769,-0.08163
25.40800,9.47769,-0.08137
25.60800,9.47769,-0.08106
25.80800,9.47769,-0.08082
26.00800,9.47769,-0.08053
26.20800,9.47769,-0.08027
26.40800,9.47769,-0.08002
26.60800,9.47769,-0.07976
26.80800,9.47769,-0.07943
27.00800,9.47769,-0.07921
27.20800,9.47769,-0.07896
27.40800,9.47769,-0.07872
27.60800,9.47769,-0.07840
27.80800,9.47769,-0.07821
28.00800,9.47769,-0.07800
28.20800,9.47769,-0.07772
28.40800,9.47769,-0.07749
28.60800,9.47769,-0.07726
28.80800,9.47769,-0.07702
29.00800,9.47769,-0.07679
29.20800,9.47769,-0.07653
29.40800,9.47769,-0.07627
29.60800,9.47769,-0.07605
29.80800,9.47769,-0.07584
30.00800,9.47769,-0.07562
30.20800,9.47769,-0.07540
30.40800,9.47769,-0.07518
30.60800,9.47769,-0.07499
30.80800,9.47769,-0.07478
31.00800,9.47769,-0.07455
31.20800,9.47769,-0.07439
31.40800,9.47769,-0.07415
31.60800,9.47769,-0.07395
31.80800,9.47769,-0.07374
32.00800,9.47769,-0.07352
32.20800,9.47769,-0.07330
32.40800,9.47769,-0.07310
32.60800,9.47769,-0.07293
32.80800,9.47769,-0.07271
33.00800,9.47769,-0.07252
33.20800,9.47769,-0.07232
33.40800,9.47769,-0.07210
33.60800,9.47769,-0.07192
33.80800,9.47769,-0.07177
34.00800,9.47769,-0.07152
34.20800,9.47769,-0.07136
34.40800,9.47769,-0.07117
34.60800,9.47769,-0.07102
34.80800,9.47769,-0.07082
35.00800,9.47769,-0.07065
35.20800,9.47769,-0.07045
35.40800,9.47769,-0.07027
35.60800,9.47769,-0.07008
35.80800,9.47769,-0.06995
36.00800,9.47769,-0.06972
36.20800,9.47769,-0.06958
36.40800,9.47769,-0.06941
36.60800,9.47769,-0.06924
36.80800,9.47769,-0.06903
37.00800,9.47769,-0.06886
37.20800,9.47769,-0.06868
37.40800,9.47769,-0.06855
37.60800,9.47769,-0.06835
37.80800,9.47769,-0.06821
38.00800,9.47769,-0.06802
38.20800,9.47769,-0.06785
38.40800,9.47769,-0.06769
38.60800,9.47769,-0.06753
38.80800,9.47769,-0.06737
39.00800,9.47769,-0.06719
39.20800,9.47769,-0.06708
39.40800,9.47769,-0.06694
39.60800,9.47769,-0.06672
39.80800,9.47769,-0.06660
40.00800,9.47769,-0.06646
40.20800,9.47769,-0.06627
40.40800,9.47769,-0.06613
40.60800,9.47769,-0.06601
40.80800,9.47769,-0.06582
41.00800,9.47769,-0.06567
41.20800,9.47769,-0.06554
41.40800,9.47769,-0.06538
41.60800,9.47769,-0.06522
41.80800,9.47769,-0.06510
42.00800,9.47769,-0.06497
42.20800,9.47769,-0.06479
42.40800,9.47769,-0.06468
42.60800,9.47769,-0.06451
42.80800,9.47769,-0.06434
43.00800,9.47769,-0.06423
43.20800,9.47769,-0.06409
43.40800,9.47769,-0.06392
43.60800,9.47769,-0.06378
43.80800,9.47769,-0.06364
44.00800,9.47769,-0.06350
44.20800,9.47769,-0.06340
44.40800,9.47769,-0.06325
44.60800,9.47769,-0.06315
44.80800,9.47769,-0.06301
45.00800,9.47769,-0.06283
45.20800,9.47769,-0.06273
45.40800,9.47769,-0.06259
45.60800,9.47769,-0.06247
45.80800,9.47769,-0.06235
46.00800,9.47769,-0.06221
46.20800,9.47769,-0.06205
46.40800,9.47769,-0.06198
46.60800,9.47769,-0.06182
46.80800,9.47769,-0.06168
47.00800,9.47769,-0.06159
47.20800,9.47769,-0.06145
47.40800,9.47769,-0.06138
47.60800,9.47769,-0.06123
47.80800,9.47769,-0.06110
48.00800,9.47769,-0.06095
48.20800,9.47769,-0.06084
48.40800,9.47769,-0.06075
48.60800,9.47769,-0.06061
48.80800,9.47769,-0.06048
49.00800,9.47769,-0.06037
49.20800,9.47769,-0.06023
49.40800,9.47769,-0.06012
49.60800,9.47769,-0.06000
49.80800,9.47769,-0.05987
50.00800,9.47769,-0.05974
50.20800,9.47769,-0.05964
50.40800,9.47769,-0.05951
50.60800,9.47769,-0.05940
50.80800,9.47769,-0.05928
51.00800,9.47769,-0.05917
51.20800,9.47769,-0.05907
51.40800,9.47769,-0.05892
51.60800,9.47769,-0.05882
51.80800,9.47769,-0.05871
52.00800,9.47769,-0.05858
52.20800,9.47769,-0.05850
52.40800,9.47769,-0.05839
52.60800,9.47769,-0.05829
52.80800,9.47769,-0.05815
53.00800,9.47769,-0.05803
53.20800,9.47769,-0.05796
53.40800,9.47769,-0.05783
53.60800,9.47769,-0.05773
53.80800,9.47769,-0.05761
54.00800,9.47769,-0.05748
54.20800,9.47769,-0.05743
54.40800,9.47769,-0.05732
54.60800,9.47769,-0.05720
54.80800,9.47769,-0.05710
55.00800,9.47769,-0.05699
55.20800,9.47769,-0.05690
55.40800,9.47769,-0.05680
55.60800,9.47769,-0.05673
55.80800,9.47769,-0.05664
56.00800,9.47769,-0.05649
56.20800,9.47769,-0.05639
56.40800,9.47769,-0.05634
56.60800,9.47769,-0.05621
56.80800,9.47769,-0.05612
57.00800,9.47769,-0.05604
57.20800,9.47769,-0.05597
57.40800,9.47769,-0.05585
57.60800,9.47769,-0.05580
57.80800,9.47769,-0.05566
58.00800,9.47769,-0.05556
58.20800,9.47769,-0.05549
58.40800,9.47769,-0.05542
58.60800,9.47769,-0.05532
58.80800,9.47769,-0.05523
59.00800,9.47769,-0.05510
59.20800,9.47769,-0.05504
59.40800,9.47769,-0.05493
59.60800,9.47769,-0.05485
59.80800,9.47769,-0.05477
60.00800,9.47769,-0.05463
60.20800,9.47769,-0.05457
60.40800,9.47769,-0.05448
60.60800,9.47769,-0.05438
60.80800,9.47769,-0.05431
61.00800,9.47769,-0.05418
61.20800,9.47769,-0.05415
61.40800,9.47769,-0.05405
61.60800,9.47769,-0.05399
61.80800,9.47769,-0.05391
62.00800,9.47769,-0.05379
62.20800,9.47769,-0.05371
62.40800,9.47769,-0.05366
62.60800,9.47769,-0.05356
62.80800,9.47769,-0.05343
63.00800,9.47769,-0.05334
63.20800,9.47769,-0.05330
63.40800,9.47769,-0.05322
63.60800,9.47769,-0.05314
63.80800,9.47769,-0.05304
64.00800,9.47769,-0.05294
64.20800,9.47769,-0.05286
64.40800,9.47769,-0.05279
64.60800,9.47769,-0.05272
64.80800,9.47769,-0.05264
65.00800,9.47769,-0.05250
65.20800,9.47769,-0.05244
65.40800,9.47769,-0.05237
65.60800,9.47769,-0.05231
65.80800,9.47769,-0.05220
66.00800,9.47769,-0.05212
66.20800,9.47769,-0.05205
66.40800,9.47769,-0.05195
66.60800,9.47769,-0.05185
66.80800,9.47769,-0.05179
67.00800,9.47769,-0.05172
67.20800,9.47769,-0.05163
67.40800,9.47769,-0.05152
67.60800,9.47769,-0.05146
67.80800,9.47769,-0.05140
68.00800,9.47769,-0.05131
68.20800,9.47769,-0.05125
68.40800,9.47769,-0.05116
68.60800,9.47769,-0.05110
68.80800,9.47769,-0.05098
69.00800,9.47769,-0.05091
69.20800,9.47769,-0.05084
69.40800,9.47769,-0.05074
69.60800,9.47769,-0.05069
69.80800,9.47769,-0.05060
70.00800,9.47769,-0.05052
70.20800,9.47769,-0.05044
70.40800,9.47769,-0.05037
70.60800,9.47769,-0.05030
70.80800,9.47769,-0.05019
71.00800,9.47769,-0.05013
71.20800,9.47769,-0.05008
71.40800,9.47769,-0.04997
71.60800,9.47769,-0.04989
71.80800,9.47769,-0.04983
72.00800,9.47769,-0.04973
72.20800,9.47769,-0.04970
72.40800,9.47769,-0.04956
72.60800,9.47769,-0.04951
72.80800,9.47769,-0.04944
73.00800,9.47769,-0.04938
73.20800,9.47769,-0.04934
73.40800,9.47769,-0.04922
73.60800,9.47769,-0.04918
73.80800,9.47769,-0.04911
74.00800,9.47769,-0.04905
74.20800,9.47769,-0.04897
74.40800,9.47769,-0.04889
74.60800,9.47769,-0.04884
74.80800,9.47769,-0.04876
75.00800,9.47769,-0.04870
75.20800,9.47769,-0.04865
75.40800,9.47769,-0.04857
75.60800,9.47769,-0.04849
75.80800,9.47769,-0.04844
76.00800,9.47769,-0.04839
76.20800,9.47769,-0.04831
76.40800,9.47769,-0.04829
76.60800,9.47769,-0.04819
76.80800,9.47769,-0.04815
77.00800,9.47769,-0.04807
77.20800,9.47769,-0.04804
77.40800,9.47769,-0.04794
77.60800,9.47769,-0.04785
77.80800,9.47769,-0.04777
78.00800,9.47769,-0.04775
78.20800,9.47769,-0.04767
78.40800,9.47769,-0.04762
78.60800,9.47769,-0.04754
78.80800,9.47769,-0.04751
79.00800,9.47769,-0.04742
79.20800,9.47769,-0.04739
79.40800,9.47769,-0.04731
79.60800,9.47769,-0.04724
79.80800,9.47769,-0.04717
80.00800,9.47769,-0.04716
80.20800,9.47769,-0.04708
80.40800,9.47769,-0.04701
80.60800,9.47769,-0.04695
80.80800,9.47769,-0.04687
81.00800,9.47769,-0.04683
81.20800,9.47769,-0.04681
81.40800,9.47769,-0.04672
81.60800,9.47769,-0.04666
81.80800,9.47769,-0.04663
82.00800,9.47769,-0.04658
82.20800,9.47769,-0.04651
82.40800,9.47769,-0.04646
82.60800,9.47769,-0.04642
82.80800,9.47769,-0.04639
83.00800,9.47769,-0.04631
83.20800,9.47769,-0.04624
83.40800,9.47769,-0.04618
83.60800,9.47769,-0.04613
83.80800,9.47769,-0.04608
84.00800,9.47769,-0.04603
84.20800,9.47769,-0.04594
84.40800,9.47769,-0.04589
84.60800,9.47769,-0.04589
84.80800,9.47769,-0.04581
85.00800,9.47769,-0.04576
85.20800,9.47769,-0.04566
85.40800,9.47769,-0.04562
85.60800,9.47769,-0.04555
85.80800,9.47769,-0.04555
86.00800,9.47769,-0.04542
86.20800,9.47769,-0.04540
86.40800,9.47769,-0.04532
86.60800,9.47769,-0.04530
86.80800,9.47769,-0.04522
87.00800,9.47769,-0.04521
87.20800,9.47769,-0.04512
87.40800,9.47769,-0.04505
87.60800,9.47769,-0.04502
87.80800,9.47769,-0.04496
88.00800,9.47769,-0.04493
88.20800,9.47769,-0.04486
88.40800,9.47769,-0.04481
88.60800,9.47769,-0.04477
88.80800,9.47769,-0.04469
89.00800,9.47769,-0.04467
89.20800,9.47769,-0.04462
89.40800,9.47769,-0.04460
89.60800,9.47769,-0.04451
89.80800,9.47769,-0.04446
90.00800,9.47769,-0.04442
90.20800,9.47769,-0.04438
90.40800,9.47769,-0.04431
90.60800,9.47769,-0.04429
90.80800,9.47769,-0.04425
91.00800,9.47769,-0.04418
91.20800,9.47769,-0.04411
91.40800,9.47769,-0.04407
91.60800,9.47769,-0.04400
91.80800,9.47769,-0.04400
92.00800,9.47769,-0.04395
92.20800,9.47769,-0.04389
92.40800,9.47769,-0.04383
92.60800,9.47769,-0.04378
92.80800,9.47769,-0.04375
93.00800,9.47769,-0.04369
93.20800,9.47769,-0.04366
93.40800,9.47769,-0.04359
93.60800,9.47769,-0.04356
93.80800,9.47769,-0.04350
94.00800,9.47769,-0.04344
94.20800,9.47769,-0.04346
94.40800,9.47769,-0.04340
94.60800,9.47769,-0.04334
94.80800,9.47769,-0.04331
95.00800,9.47769,-0.04322
95.20800,9.47769,-0.04318
95.40800,9.47769,-0.04316
95.60800,9.47769,-0.04309
95.80800,9.47769,-0.04311
96.00800,9.47769,-0.04305
96.20800,9.47769,-0.04298
96.40800,9.47769,-0.04293
96.60800,9.47769,-0.04286
96.80800,9.47769,-0.04286
97.00800,9.47769,-0.04277
97.20800,9.47769,-0.04272
97.40800,9.47769,-0.04270
97.60800,9.47769,-0.04267
97.80800,9.47769,-0.04260
98.00800,9.47769,-0.04258
98.20800,9.47769,-0.04251
98.40800,9.47769,-0.04246
98.60800,9.47769,-0.04240
98.80800,9.47769,-0.04235
99.00800,9.47769,-0.04234
99.20800,9.47769,-0.04232
99.40800,9.47769,-0.04229
99.60800,9.47769,-0.04220
99.80800,9.47769,-0.04218
100.00800,9.47769,-0.04216
100.20800,9.47769,-0.04213
100.40800,9.47769,-0.04211
100.60800,9.47769,-0.04206
100.80800,9.47769,-0.04200
101.00800,9.47769,-0.04193
101.20800,9.47769,-0.04190
101.40800,9.47769,-0.04187
101.60800,9.47769,-0.04182
101.80800,9.47769,-0.04176
102.00800,9.47769,-0.04175
102.20800,9.47769,-0.04170
102.40800,9.47769,-0.04166
102.60800,9.47769,-0.04164
102.80800,9.47769,-0.04159
103.00800,9.47769,-0.04157
103.20800,9.47769,-0.04148
103.40800,9.47769,-0.04150
103.60800,9.47769,-0.04141
103.80800,9.47769,-0.04139
104.00800,9.47769,-0.04138
104.20800,9.47769,-0.04134
104.40800,9.47769,-0.04126
104.60800,9.47769,-0.04123
104.80800,9.47769,-0.04119
105.00800,9.47769,-0.04118
105.20800,9.47769,-0.04115
105.40801,9.47769,-0.04111
105.60801,9.47769,-0.04107
105.80801,9.47769,-0.04105
106.00801,9.47769,-0.04099
106.20801,9.47769,-0.04096
106.40801,9.47769,-0.04094
106.60801,9.47769,-0.04086
106.80801,9.47769,-0.04082
107.00801,9.47769,-0.04081
107.20801,9.47769,-0.04071
107.40801,9.47769,-0.04070
107.60801,9.47769,-0.04068
107.80801,9.47769,-0.04063
108.00801,9.47769,-0.04057
108.20801,9.47769,-0.04056
108.40801,9.47769,-0.04050
108.60801,9.47769,-0.04048
108.80801,9.47769,-0.04045
109.00801,9.47769,-0.04042
109.20801,9.47769,-0.04037
109.40801,9.47769,-0.04032
109.60801,9.47769,-0.04026
109.80801,9.47769,-0.04022
110.00801,9.47769,-0.04016
110.20801,9.47769,-0.04017
110.40801,9.47769,-0.04013
110.60801,9.47769,-0.04005
110.80801,9.47769,-0.04004
111.00801,9.47769,-0.04001
111.20801,9.47769,-0.03995
111.40801,9.47769,-0.03989
111.60801,9.47769,-0.03987
111.80801,9.47769,-0.03988
112.00801,9.47769,-0.03980
112.20801,9.47769,-0.03976
112.40801,9.47769,-0.03972
112.60801,9.47769,-0.03973
112.80801,9.47769,-0.03965
113.00801,9.47769,-0.03962
113.20801,9.47769,-0.03960
113.40801,9.47769,-0.03955
113.60801,9.47769,-0.03954
113.80801,9.47769,-0.03950
114.00801,9.47769,-0.03949
114.20801,9.47769,-0.03944
114.40801,9.47769,-0.03941
114.60801,9.47769,-0.03937
114.80801,9.47769,-0.03931
115.00801,9.47769,-0.03930
115.20801,9.47769,-0.03930
115.40801,9.47769,-0.03922
115.60801,9.47769,-0.03919
115.80801,9.47769,-0.03917
116.00801,9.47769,-0.03913
116.20801,9.47769,-0.03906
116.40801,9.47769,-0.03906
116.60801,9.47769,-0.03900
116.80801,9.47769,-0.03892
117.00801,9.47769,-0.03893
117.20801,9.47769,-0.03890
117.40801,9.47769,-0.03883
117.60801,9.47769,-0.03881
117.80801,9.47769,-0.03877
118.00801,9.47769,-0.03874
118.20801,9.47769,-0.03870
118.40801,9.47769,-0.03868
118.60801,9.47769,-0.03866
118.80801,9.47769,-0.03860
119.00801,9.47769,-0.03855
119.20801,9.47769,-0.03852
119.40801,9.47769,-0.03849
119.60801,9.47769,-0.03849
119.80801,9.47769,-0.03847
120.00801,9.47769,-0.03841
120.20801,9.47769,-0.03838
120.40801,9.47769,-0.03832
120.60801,9.47769,-0.03831
120.80801,9.47769,-0.03828
121.00801,9.47769,-0.03827
121.20801,9.47769,-0.03824
121.40801,9.47769,-0.03820
121.60801,9.47769,-0.03816
121.80801,9.47769,-0.03814
122.00801,9.47769,-0.03811
122.20801,9.47769,-0.03809
122.40801,9.47769,-0.03803
122.60801,9.47769,-0.03803
122.80801,9.47769,-0.03795
123.00801,9.47769,-0.03797
123.20801,9.47769,-0.03787
123.40801,9.47769,-0.03790
123.60801,9.47769,-0.03787
123.80801,9.47769,-0.03783
124.00801,9.47769,-0.03776
124.20801,9.47769,-0.03776
124.40801,9.47769,-0.03767
124.60801,9.47769,-0.03770
124.80801,9.47769,-0.03763
125.00801,9.47769,-0.03765
125.20801,9.47769,-0.03761
125.40801,9.47769,-0.03757
125.60801,9.47769,-0.03756
125.80801,9.47769,-0.03754
126.00801,9.47769,-0.03749
126.20801,9.47769,-0.03745
126.40801,9.47769,-0.03741
126.60801,9.47769,-0.03743
126.80801,9.47769,-0.03738
127.00801,9.47769,-0.03733
127.20801,9.47769,-0.03733
127.40801,9.47769,-0.03727
127.60801,9.47769,-0.03725
127.80801,9.47769,-0.03721
128.00801,9.47769,-0.03717
128.20801,9.47769,-0.03718
128.40801,9.47769,-0.03712
128.60801,9.47769,-0.03710
128.80801,9.47769,-0.03706
129.00801,9.47769,-0.03706
129.20801,9.47769,-0.03703
129.40801,9.47769,-0.03700
129.60801,9.47769,-0.03697
129.80801,9.47769,-0.03692
130.00801,9.47769,-0.03687
130.20801,9.47769,-0.03686
130.40801,9.47769,-0.03683
130.60801,9.47769,-0.03681
130.80801,9.47769,-0.03677
131.00801,9.47769,-0.03675
131.20801,9.47769,-0.03674
131.40801,9.47769,-0.03671
131.60801,9.47769,-0.03664
131.80801,9.47769,-0.03667
132.00801,9.47769,-0.03661
132.20801,9.47769,-0.03658
132.40801,9.47769,-0.03656
132.60801,9.47769,-0.03653
132.80801,9.47769,-0.03649
133.00801,9.47769,-0.03646
133.20801,9.47769,-0.03646
133.40801,9.47769,-0.03642
133.60801,9.47769,-0.03638
133.80801,9.47769,-0.03636
134.00801,9.47769,-0.03638
134.20801,9.47769,-0.03631
134.40801,9.47769,-0.03629
134.60801,9.47769,-0.03626
134.80801,9.47769,-0.03625
135.00801,9.47769,-0.03618
135.20801,9.47769,-0.03621
135.40801,9.47769,-0.03615
135.60801,9.47769,-0.03610
135.80801,9.47769,-0.03610
136.00801,9.47769,-0.03610
136.20801,9.47769,-0.03605
136.40801,9.47769,-0.03603
136.60801,9.47769,-0.03599
136.80801,9.47769,-0.03595
137.00801,9.47769,-0.03591
137.20801,9.47769,-0.03595
137.40801,9.47769,-0.03591
137.60801,9.47769,-0.03588
137.80801,9.47769,-0.03581
138.00801,9.47769,-0.03583
138.20801,9.47769,-0.03581
138.40801,9.47769,-0.03579
138.60801,9.47769,-0.03579
138.80801,9.47769,-0.03579
139.00801,9.47769,-0.03575
139.20801,9.47769,-0.03573
139.40801,9.47769,-0.03573
139.60801,9.47769,-0.03569
139.80801,9.47769,-0.03565
140.00801,9.47769,-0.03562
140.20801,9.47769,-0.03561
140.40801,9.47769,-0.03557
140.60801,9.47769,-0.03555
140.80801,9.47769,-0.03553
141.00801,9.47769,-0.03546
141.20801,9.47769,-0.03545
141.40801,9.47769,-0.03543
141.60801,9.47769,-0.03541
141.80801,9.47769,-0.03536
142.00801,9.47769,-0.03533
142.20801,9.47769,-0.03533
142.40801,9.47769,-0.03533
142.60801,9.47769,-0.03531
142.80801,9.47769,-0.03528
143.00801,9.47769,-0.03527
143.20801,9.47769,-0.03521
143.40801,9.47769,-0.03522
143.60801,9.47769,-0.03518
143.80801,9.47769,-0.03514
144.00801,9.47769,-0.03514
144.20801,9.47769,-0.03511
144.40801,9.47769,-0.03507
144.60801,9.47769,-0.03504
144.80801,9.47769,-0.03506
145.00801,9.47769,-0.03501
145.20801,9.47769,-0.03496
145.40801,9.47769,-0.03500
145.60801,9.47769,-0.03496
145.80801,9.47769,-0.03489
146.00801,9.47769,-0.03488
146.20801,9.47769,-0.03487
146.40801,9.47769,-0.03486
146.60801,9.47769,-0.03480
146.80801,9.47769,-0.03481
147.00801,9.47769,-0.03475
147.20801,9.47769,-0.03471
147.40801,9.47769,-0.03472
147.60801,9.47769,-0.03469
147.80801,9.47769,-0.03467
148.00801,9.47769,-0.03461
148.20801,9.47769,-0.03461
148.40801,9.47769,-0.03459
148.60801,9.47769,-0.03453
148.80801,9.47769,-0.03459
149.00801,9.47769,-0.03452
149.20801,9.47769,-0.03452
149.40801,9.47769,-0.03448
149.60801,9.47769,-0.03445
149.80801,9.47769,-0.03441
150.00801,9.47769,-0.03441
150.20801,9.47769,-0.03437
150.40801,9.47769,-0.03436
150.60801,9.47769,-0.03432
150.80801,9.47769,-0.03429
151.00801,9.47769,-0.03434
151.20801,9.47769,-0.03424
151.40801,9.47769,-0.03427
151.60801,9.47769,-0.03423
151.80801,9.47769,-0.03416
152.00801,9.47769,-0.03420
152.20801,9.47769,-0.03416
152.40801,9.47769,-0.03414
152.60801,9.47769,-0.03408
152.80801,9.47769,-0.03405
153.00801,9.47769,-0.03405
153.20801,9.47769,-0.03401
153.40801,9.47769,-0.03399
153.60801,9.47769,-0.03399
153.80801,9.47769,-0.03397
154.00801,9.47769,-0.03393
154.20801,9.47769,-0.03392
154.40801,9.47769,-0.03391
154.60801,9.47769,-0.03386
154.80801,9.47769,-0.03386
155.00801,9.47769,-0.03383
155.20801,9.47769,-0.03383
155.40801,9.47769,-0.03380
155.60801,9.47769,-0.03381
155.80801,9.47769,-0.03374
156.00801,9.47769,-0.03371
156.20801,9.47769,-0.03368
156.40801,9.47769,-0.03368
156.60801,9.47769,-0.03365
156.80801,9.47769,-0.03362
157.00801,9.47769,-0.03361
157.20801,9.47769,-0.03359
157.40801,9.47769,-0.03357
157.60801,9.47769,-0.03356
157.80801,9.47769,-0.03354
158.00801,9.47769,-0.03355
158.20801,9.47769,-0.03348
158.40801,9.47769,-0.03343
158.60801,9.47769,-0.03340
158.80801,9.47769,-0.03345
159.00801,9.47769,-0.03341
159.20801,9.47769,-0.03340
159.40801,9.47769,-0.03334
159.60801,9.47769,-0.03333
159.80801,9.47769,-0.03333
160.00801,9.47769,-0.03329
160.20801,9.47769,-0.03327
160.40801,9.47769,-0.03326
160.60801,9.47769,-0.03323
160.80801,9.47769,-0.03321
161.00801,9.47769,-0.03321
161.20801,9.47769,-0.03318
161.40801,9.47769,-0.03315
161.60801,9.47769,-0.03314
161.80801,9.47769,-0.03312
162.00801,9.47769,-0.03312
162.20801,9.47769,-0.03307
162.40801,9.47769,-0.03309
162.60801,9.47769,-0.03306
162.80801,9.47769,-0.03301
163.00801,9.47769,-0.03304
163.20801,9.47769,-0.03297
163.40801,9.47769,-0.03297
163.60801,9.47769,-0.03298
163.80801,9.47769,-0.03295
164.00801,9.47769,-0.03290
164.20801,9.47769,-0.03291
164.40801,9.47769,-0.03289
164.60801,9.47769,-0.03287
164.80801,9.47769,-0.03288
165.00801,9.47769,-0.03285
165.20801,9.47769,-0.03280
165.40801,9.47769,-0.03279
165.60801,9.47769,-0.03281
165.80801,9.47769,-0.03275
166.00801,9.47769,-0.03271
166.20801,9.47769,-0.03269
166.40801,9.47769,-0.03270
166.60801,9.47769,-0.03270
166.80801,9.47769,-0.03266
167.00801,9.47769,-0.03266
167.20801,9.47769,-0.03261
167.40801,9.47769,-0.03261
167.60801,9.47769,-0.03260
167.80801,9.47769,-0.03261
168.00801,9.47769,-0.03255
168.20801,9.47769,-0.03252
168.40801,9.47769,-0.03252
168.60801,9.47769,-0.03252
168.80801,9.47769,-0.03248
169.00801,9.47769,-0.03247
169.20801,9.47769,-0.03244
169.40801,9.47769,-0.03243
169.60801,9.47769,-0.03242
169.80801,9.47769,-0.03238
170.00801,9.47769,-0.03237
170.20801,9.47769,-0.03233
170.40801,9.47769,-0.03234
170.60801,9.47769,-0.03228
170.80801,9.47769,-0.03228
171.00801,9.47769,-0.03226
171.20801,9.47769,-0.03224
171.40801,9.47769,-0.03217
171.60801,9.47769,-0.03221
171.80801,9.47769,-0.03212
172.00801,9.47769,-0.03213
172.20801,9.47769,-0.03211
172.40801,9.47769,-0.03213
172.60801,9.47769,-0.03210
172.80801,9.47769,-0.03207
173.00801,9.47769,-0.03208
173.20801,9.47769,-0.03201
173.40801,9.47769,-0.03199
173.60801,9.47769,-0.03199
173.80801,9.47769,-0.03196
174.00801,9.47769,-0.03192
174.20801,9.47769,-0.03191
174.40801,9.47769,-0.03191
174.60801,9.47769,-0.03187
174.80801,9.47769,-0.03188
175.00801,9.47769,-0.03182
175.20801,9.47769,-0.03179
175.40801,9.47769,-0.03181
175.60801,9.47769,-0.03179
175.80801,9.47769,-0.03177
176.00801,9.47769,-0.03172
176.20801,9.47769,-0.03173
176.40801,9.47769,-0.03166
176.60801,9.47769,-0.03167
176.80801,9.47769,-0.03169
177.00801,9.47769,-0.03166
177.20801,9.47769,-0.03166
177.40801,9.47769,-0.03162
177.60801,9.47769,-0.03166
177.80801,9.47769,-0.03156
178.00801,9.47769,-0.03155
178.20801,9.47769,-0.03157
178.40801,9.47769,-0.03155
178.60801,9.47769,-0.03148
178.80801,9.47769,-0.03150
179.00801,9.47769,-0.03147
179.20801,9.47769,-0.03147
179.40801,9.47769,-0.03145
179.60801,9.47769,-0.03146
179.80801,9.47769,-0.03139
180.00801,9.47769,-0.03139
180.20801,9.47769,-0.03139
180.40801,9.47769,-0.03135
180.60801,9.47769,-0.03134
180.80801,9.47769,-0.03129
181.00801,9.47769,-0.03130
181.20801,9.47769,-0.03130
181.40801,9.47769,-0.03128
181.60801,9.47769,-0.03125
181.80801,9.47769,-0.03125
182.00801,9.47769,-0.03123
182.20801,9.47769,-0.03122
182.40801,9.47769,-0.03121
182.60801,9.47769,-0.03119
182.80801,9.47769,-0.03118
183.00801,9.47769,-0.03117
183.20801,9.47769,-0.03113
183.40801,9.47769,-0.03112
183.60801,9.47769,-0.03111
183.80801,9.47769,-0.03107
184.00801,9.47769,-0.03104
184.20801,9.47769,-0.03108
184.40801,9.47769,-0.03103
184.60801,9.47769,-0.03102
184.80801,9.47769,-0.03100
185.00801,9.47769,-0.03100
185.20801,9.47769,-0.03098
185.40801,9.47769,-0.03102
185.60801,9.47769,-0.03097
185.80801,9.47769,-0.03093
186.00801,9.47769,-0.03093
186.20801,9.47769,-0.03092
186.40801,9.47769,-0.03089
186.60801,9.47769,-0.03085
186.80801,9.47769,-0.03084
187.00801,9.47769,-0.03082
187.20801,9.47769,-0.03080
187.40801,9.47769,-0.03083
187.60801,9.47769,-0.03076
187.80801,9.47769,-0.03076
188.00801,9.47769,-0.03073
188.20801,9.47769,-0.03076
188.40801,9.47769,-0.03071
188.60801,9.47769,-0.03070
188.80801,9.47769,-0.03068
189.00801,9.47769,-0.03065
189.20801,9.47769,-0.03061
189.40801,9.47769,-0.03063
189.60801,9.47769,-0.03059
189.80801,9.47769,-0.03058
190.00801,9.47769,-0.03057