File: reference/original_matlab_code/ViscoelasticAnalysis/Sample Instron Files/Specimen_RawData_2.csv
Time,Extension,Load
(sec),(mm),(N)
0.00000,9.93936,0.00006
0.20000,9.93665,-0.00019
0.40000,9.92102,-0.00213
0.60000,9.91019,-0.00354
0.80000,9.90019,-0.00492
1.00000,9.88998,-0.00642
1.20000,9.87998,-0.00803
1.40000,9.87019,-0.00971
1.60000,9.86019,-0.01147
1.80000,9.84998,-0.01341
2.00000,9.83998,-0.01544
2.20000,9.83040,-0.01741
2.40000,9.82040,-0.01956
2.60000,9.80998,-0.02190
2.80000,9.79977,-0.02434
3.00000,9.78998,-0.02665
3.20000,9.78019,-0.02909
3.40000,9.76977,-0.03168
3.60000,9.75936,-0.03451
3.80000,9.74977,-0.03701
4.00000,9.73998,-0.03969
4.20000,9.72977,-0.04257
4.40000,9.71915,-0.04562
4.60000,9.70978,-0.04842
4.80000,9.70019,-0.05118
5.00000,9.68998,-0.05440
5.20000,9.67936,-0.05767
5.40000,9.66978,-0.06066
5.60000,9.66019,-0.06376
5.80000,9.64977,-0.06720
6.00000,9.63978,-0.07056
6.20000,9.63019,-0.07380
6.40000,9.62040,-0.07710
6.60000,9.60978,-0.08092
6.80000,9.59978,-0.08446
7.00000,9.58998,-0.08787
7.20000,9.57998,-0.09146
7.40000,9.56915,-0.09573
7.60000,9.55957,-0.09928
7.80000,9.54998,-0.10294
8.00000,9.54019,-0.10662
8.20000,9.52936,-0.11105
8.40000,9.51957,-0.11493
8.60000,9.50978,-0.11872
8.80000,9.49998,-0.12266
9.00000,9.48978,-0.12700
9.20000,9.47957,-0.13126
9.40000,9.46957,-0.13550
9.60000,9.45998,-0.13959
9.80000,9.44957,-0.14408
10.00000,9.43998,-0.14826
10.01000,9.43957,-0.14845
10.21000,9.43811,-0.14766
10.41000,9.43811,-0.14580
10.61000,9.43811,-0.14417
10.81000,9.43811,-0.14275
11.01000,9.43811,-0.14144
11.21000,9.43853,-0.14020
11.41000,9.43853,-0.13895
11.61000,9.43873,-0.13776
11.81000,9.43873,-0.13663
12.01000,9.43894,-0.13553
12.21000,9.43915,-0.13449
12.41000,9.43915,-0.13351
12.61000,9.43936,-0.13255
12.81000,9.43936,-0.13161
13.01000,9.43936,-0.13074
13.21000,9.43957,-0.12984
13.41000,9.43957,-0.12906
13.61000,9.43957,-0.12823
13.81000,9.43957,-0.12751
14.01000,9.43957,-0.12674
14.21000,9.43957,-0.12602
14.41000,9.43957,-0.12536
14.61000,9.43957,-0.12460
14.81000,9.43957,-0.12388
15.01000,9.43957,-0.12328
15.21000,9.43957,-0.12259
15.41000,9.43957,-0.12191
15.61000,9.43957,-0.12121
15.81000,9.43957,-0.12059
16.01000,9.43957,-0.11998
16.21000,9.43957,-0.11941
16.41000,9.43957,-0.11877
16.61000,9.43957,-0.11816
16.81000,9.43957,-0.11758
17.01000,9.43957,-0.11703
17.21000,9.43957,-0.11645
17.41000,9.43957,-0.11589
17.61000,9.43957,-0.11536
17.81000,9.43957,-0.11480
18.01000,9.43957,-0.11427
18.21000,9.43957,-0.11377
18.41000,9.43957,-0.11324
18.61000,9.43957,-0.11273
18.81000,9.43957,-0.11222
19.01000,9.43957,-0.11177
19.21000,9.43957,-0.11126
19.41000,9.43957,-0.11079
19.61000,9.43957,-0.11027
19.81000,9.43957,-0.10983
20.01000,9.43957,-0.10938
20.21000,9.43957,-0.10893
20.41000,9.43957,-0.10846
20.61000,9.43957,-0.10802
20.81000,9.43957,-0.10761
21.01000,9.43957,-0.10717
21.21000,9.43957,-0.10676
21.41000,9.43957,-0.10638
21.61000,9.43957,-0.10593
21.81000,9.43957,-0.10546
22.01000,9.43957,-0.10507
22.21000,9.43957,-0.10469
22.41000,9.43957,-0.10428
22.61000,9.43957,-0.10388
22.81000,9.43957,-0.10352
23.01000,9.43957,-0.10311
23.21000,9.43957,-0.10275
23.41000,9.43957,-0.10234
23.61000,9.43957,-0.10198
23.81000,9.43957,-0.10156
24.01000,9.43957,-0.10125
24.21000,9.43957,-0.10091
24.41000,9.43957,-0.10052
24.61000,9.43957,-0.10016
24.81000,9.43957,-0.09977
25.01000,9.43957,-0.09945
25.21000,9.43957,-0.09911
25.41000,9.43957,-0.09878
25.61000,9.43957,-0.09845
25.81000,9.43957,-0.09803
26.01000,9.43957,-0.09774
26.21000,9.43957,-0.09740
26.41000,9.43957,-0.09704
26.61000,9.43957,-0.09670
26.81000,9.43957,-0.09640
27.01000,9.43957,-0.09604
27.21000,9.43957,-0.09577
27.41000,9.43957,-0.09545
27.61000,9.43957,-0.09513
27.81000,9.43957,-0.09486
28.01000,9.43957,-0.09459
28.21000,9.43957,-0.09423
28.41000,9.43957,-0.09393
28.61000,9.43957,-0.09366
28.81000,9.43957,-0.09332
29.01000,9.43957,-0.09308
29.21000,9.43957,-0.09274
29.41000,9.43957,-0.09244
29.61000,9.43957,-0.09221
29.81000,9.43957,-0.09190
30.01000,9.43957,-0.09160
30.21000,9.43957,-0.09135
30.41000,9.43957,-0.09108
30.61000,9.43957,-0.09080
30.81000,9.43957,-0.09048
31.01000,9.43957,-0.09026
31.21000,9.43957,-0.08996
31.41000,9.43957,-0.08971
31.61000,9.43957,-0.08942
31.81000,9.43957,-0.08918
32.01000,9.43957,-0.08890
32.21000,9.43957,-0.08866
32.41000,9.43957,-0.08835
32.61000,9.43957,-0.08817
32.81000,9.43957,-0.08789
33.01000,9.43957,-0.08759
33.21000,9.43957,-0.08740
33.41000,9.43957,-0.08711
33.61000,9.43957,-0.08692
33.81000,9.43957,-0.08665
34.01000,9.43957,-0.08639
34.21000,9.43957,-0.08616
34.41000,9.43957,-0.08595
34.61000,9.43957,-0.08568
34.81000,9.43957,-0.08547
35.01000,9.43957,-0.08521
35.21000,9.43957,-0.08497
35.41000,9.43957,-0.08477
35.61000,9.43957,-0.08455
35.81000,9.43957,-0.08429
36.01000,9.43957,-0.08406
36.21000,9.43957,-0.08387
36.41000,9.43957,-0.08365
36.61000,9.43957,-0.08341
36.81000,9.43957,-0.08321
37.01000,9.43957,-0.08297
37.21000,9.43957,-0.08272
37.41000,9.43957,-0.08255
37.61000,9.43957,-0.08232
37.81000,9.43957,-0.08208
38.01000,9.43957,-0.08190
38.21000,9.43957,-0.08166
38.41000,9.43957,-0.08148
38.61000,9.43957,-0.08126
38.81000,9.43957,-0.08105
39.01000,9.43957,-0.08081
39.21000,9.43957,-0.08064
39.41000,9.43957,-0.08047
39.61000,9.43957,-0.08027
39.81000,9.43957,-0.08004
40.01000,9.43957,-0.07985
40.21000,9.43957,-0.07968
40.41000,9.43957,-0.07946
40.61000,9.43957,-0.07930
40.81000,9.43957,-0.07909
41.01000,9.43957,-0.07891
41.21000,9.43957,-0.07873
41.41000,9.43957,-0.07855
41.61000,9.43957,-0.07834
41.81000,9.43957,-0.07819
42.01000,9.43957,-0.07799
42.21000,9.43957,-0.07784
42.41000,9.43957,-0.07761
42.61000,9.43957,-0.07747
42.81000,9.43957,-0.07726
43.01000,9.43957,-0.07713
43.21000,9.43957,-0.07695
43.41000,9.43957,-0.07680
43.61000,9.43957,-0.07664
43.81000,9.43957,-0.07645
44.01000,9.43957,-0.07627
44.21000,9.43957,-0.07610
44.41000,9.43957,-0.07595
44.61000,9.43957,-0.07579
44.81000,9.43957,-0.07562
45.01000,9.43957,-0.07539
45.21000,9.43957,-0.07525
45.41000,9.43957,-0.07513
45.61000,9.43957,-0.07493
45.81000,9.43957,-0.07478
46.01000,9.43957,-0.07462
46.21000,9.43957,-0.07445
46.41000,9.43957,-0.07428
46.61000,9.43957,-0.07411
46.81000,9.43957,-0.07398
47.01000,9.43957,-0.07380
47.21000,9.43957,-0.07366
47.41000,9.43957,-0.07351
47.61000,9.43957,-0.07336
47.81000,9.43957,-0.07317
48.01000,9.43957,-0.07301
48.21000,9.43957,-0.07288
48.41000,9.43957,-0.07272
48.61000,9.43957,-0.07260
48.81000,9.43957,-0.07241
49.01000,9.43957,-0.07226
49.21000,9.43957,-0.07210
49.41000,9.43957,-0.07200
49.61000,9.43957,-0.07184
49.81000,9.43957,-0.07170
50.01000,9.43957,-0.07154
50.21000,9.43957,-0.07140
50.41000,9.43957,-0.07126
50.61000,9.43957,-0.07113
50.81000,9.43957,-0.07098
51.01000,9.43957,-0.07085
51.21000,9.43957,-0.07070
51.41000,9.43957,-0.07056
51.61000,9.43957,-0.07044
51.81000,9.43957,-0.07028
52.01000,9.43957,-0.07017
52.21000,9.43957,-0.07002
52.41000,9.43957,-0.06989
52.61000,9.43957,-0.06978
52.81000,9.43957,-0.06966
53.01000,9.43957,-0.06953
53.21000,9.43957,-0.06938
53.41000,9.43957,-0.06925
53.61000,9.43957,-0.06912
53.81000,9.43957,-0.06902
54.01000,9.43957,-0.06886
54.21000,9.43957,-0.06872
54.41000,9.43957,-0.06860
54.61000,9.43957,-0.06844
54.81000,9.43957,-0.06830
55.01000,9.43957,-0.06817
55.21000,9.43957,-0.06805
55.41000,9.43957,-0.06795
55.61000,9.43957,-0.06780
55.81000,9.43957,-0.06770
56.01000,9.43957,-0.06755
56.21000,9.43957,-0.06739
56.41000,9.43957,-0.06730
56.61000,9.43957,-0.06719
56.81000,9.43957,-0.06708
57.01000,9.43957,-0.06695
57.21000,9.43957,-0.06682
57.41000,9.43957,-0.06673
57.61000,9.43957,-0.06662
57.81000,9.43957,-0.06647
58.01000,9.43957,-0.06635
58.21000,9.43957,-0.06627
58.41000,9.43957,-0.06612
58.61000,9.43957,-0.06603
58.81000,9.43957,-0.06587
59.01000,9.43957,-0.06576
59.21000,9.43957,-0.06567
59.41000,9.43957,-0.06554
59.61000,9.43957,-0.06540
59.81000,9.43957,-0.06532
60.01000,9.43957,-0.06518
60.21000,9.43957,-0.06510
60.41000,9.43957,-0.06496
60.61000,9.43957,-0.06487
60.81000,9.43957,-0.06478
61.01000,9.43957,-0.06463
61.21000,9.43957,-0.06455
61.41000,9.43957,-0.06445
61.61000,9.43957,-0.06435
61.81000,9.43957,-0.06425
62.01000,9.43957,-0.06415
62.21000,9.43957,-0.06401
62.41000,9.43957,-0.06394
62.61000,9.43957,-0.06381
62.81000,9.43957,-0.06372
63.01000,9.43957,-0.06361
63.21000,9.43957,-0.06351
63.41000,9.43957,-0.06340
63.61000,9.43957,-0.06329
63.81000,9.43957,-0.06319
64.01000,9.43957,-0.06311
64.21000,9.43957,-0.06300
64.41000,9.43957,-0.06290
64.61000,9.43957,-0.06281
64.81000,9.43957,-0.06270
65.01000,9.43957,-0.06257
65.21000,9.43957,-0.06249
65.41000,9.43957,-0.06238
65.61000,9.43957,-0.06231
65.81000,9.43957,-0.06218
66.01000,9.43957,-0.06214
66.21000,9.43957,-0.06201
66.41000,9.43957,-0.06193
66.61000,9.43957,-0.06183
66.81000,9.43957,-0.06174
67.01000,9.43957,-0.06161
67.21000,9.43957,-0.06157
67.41000,9.43957,-0.06147
67.61000,9.43957,-0.06133
67.81000,9.43957,-0.06130
68.01000,9.43957,-0.06120
68.21000,9.43957,-0.06107
68.41000,9.43957,-0.06102
68.61000,9.43957,-0.06090
68.81000,9.43957,-0.06079
69.01000,9.43957,-0.06073
69.21000,9.43957,-0.06063
69.41000,9.43957,-0.06053
69.61000,9.43957,-0.06043
69.81000,9.43957,-0.06035
70.01000,9.43957,-0.06026
70.21000,9.43957,-0.06016
70.41000,9.43957,-0.06008
70.61000,9.43957,-0.06002
70.81000,9.43957,-0.05992
71.01000,9.43957,-0.05984
71.21000,9.43957,-0.05974
71.41000,9.43957,-0.05962
71.61000,9.43957,-0.05954
71.81000,9.43957,-0.05946
72.01000,9.43957,-0.05935
72.21000,9.43957,-0.05930
72.41000,9.43957,-0.05922
72.61000,9.43957,-0.05915
72.81000,9.43957,-0.05904
73.01000,9.43957,-0.05895
73.21000,9.43957,-0.05892
73.41000,9.43957,-0.05882
73.61000,9.43957,-0.05872
73.81000,9.43957,-0.05863
74.01000,9.43957,-0.05855
74.21000,9.43957,-0.05848
74.41000,9.43957,-0.05837
74.61000,9.43957,-0.05833
74.81000,9.43957,-0.05822
75.01000,9.43957,-0.05810
75.21000,9.43957,-0.05803
75.41000,9.43957,-0.05793
75.61000,9.43957,-0.05783
75.81000,9.43957,-0.05778
76.01000,9.43957,-0.05768
76.21000,9.43957,-0.05763
76.41000,9.43957,-0.05753
76.61000,9.43957,-0.05743
76.81000,9.43957,-0.05736
77.01000,9.43957,-0.05730
77.21000,9.43957,-0.05721
77.41000,9.43957,-0.05712
77.61000,9.43957,-0.05704
77.81000,9.43957,-0.05693
78.01000,9.43957,-0.05688
78.21000,9.43957,-0.05684
78.41000,9.43957,-0.05672
78.61000,9.43957,-0.05665
78.81000,9.43957,-0.05658
79.01000,9.43957,-0.05653
79.21000,9.43957,-0.05642
79.41000,9.43957,-0.05639
79.61000,9.43957,-0.05627
79.81000,9.43957,-0.05621
80.01000,9.43957,-0.05614
80.21000,9.43957,-0.05608
80.41000,9.43957,-0.05600
80.61000,9.43957,-0.05595
80.81000,9.43957,-0.05582
81.01000,9.43957,-0.05574
81.21000,9.43957,-0.05571
81.41000,9.43957,-0.05563
81.61000,9.43957,-0.05554
81.81000,9.43957,-0.05548
82.01000,9.43957,-0.05540
82.21000,9.43957,-0.05535
82.41000,9.43957,-0.05524
82.61000,9.43957,-0.05519
82.81000,9.43957,-0.05511
83.01000,9.43957,-0.05504
83.21000,9.43957,-0.05496
83.41000,9.43957,-0.05489
83.61000,9.43957,-0.05482
83.81000,9.43957,-0.05476
84.01000,9.43957,-0.05468
84.21000,9.43957,-0.05462
84.41000,9.43957,-0.05451
84.61000,9.43957,-0.05453
84.81000,9.43957,-0.05436
85.01000,9.43957,-0.05433
85.21000,9.43957,-0.05427
85.41000,9.43957,-0.05419
85.61000,9.43957,-0.05412
85.81000,9.43957,-0.05405
86.01000,9.43957,-0.05401
86.21000,9.43957,-0.05393
86.41000,9.43957,-0.05382
86.61000,9.43957,-0.05379
86.81000,9.43957,-0.05374
87.01000,9.43957,-0.05364
87.21000,9.43957,-0.05358
87.41000,9.43957,-0.05353
87.61000,9.43957,-0.05344
87.81000,9.43957,-0.05341
88.01000,9.43957,-0.05334
88.21000,9.43957,-0.05326
88.41000,9.43957,-0.05319
88.61000,9.43957,-0.05318
88.81000,9.43957,-0.05304
89.01000,9.43957,-0.05300
89.21000,9.43957,-0.05294
89.41000,9.43957,-0.05286
89.61000,9.43957,-0.05279
89.81000,9.43957,-0.05272
90.01000,9.43957,-0.05266
90.21000,9.43957,-0.05261
90.41000,9.43957,-0.05253
90.61000,9.43957,-0.05248
90.81000,9.43957,-0.05244
91.01000,9.43957,-0.05236
91.21000,9.43957,-0.05231
91.41000,9.43957,-0.05224
91.61000,9.43957,-0.05218
91.81000,9.43957,-0.05210
92.01000,9.43957,-0.05210
92.21000,9.43957,-0.05202
92.41000,9.43957,-0.05197
92.61000,9.43957,-0.05193
92.81000,9.43957,-0.05186
93.01000,9.43957,-0.05178
93.21000,9.43957,-0.05175
93.41000,9.43957,-0.05170
93.61000,9.43957,-0.05160
93.81000,9.43957,-0.05159
94.01000,9.43957,-0.05151
94.21000,9.43957,-0.05144
94.41000,9.43957,-0.05138
94.61000,9.43957,-0.05134
94.81000,9.43957,-0.05127
95.01000,9.43957,-0.05123
95.21000,9.43957,-0.05117
95.41000,9.43957,-0.05109
95.61000,9.43957,-0.05105
95.81000,9.43957,-0.05099
96.01000,9.43957,-0.05092
96.21000,9.43957,-0.05086
96.41000,9.43957,-0.05083
96.61000,9.43957,-0.05072
96.81000,9.43957,-0.05072
97.01000,9.43957,-0.05062
97.21000,9.43957,-0.05059
97.41000,9.43957,-0.05048
97.61000,9.43957,-0.05046
97.81000,9.43957,-0.05042
98.01000,9.43957,-0.05036
98.21000,9.43957,-0.05028
98.41000,9.43957,-0.05026
98.61000,9.43957,-0.05018
98.81000,9.43957,-0.05011
99.01000,9.43957,-0.05007
99.21000,9.43957,-0.05000
99.41000,9.43957,-0.04993
99.61000,9.43957,-0.04987
99.81000,9.43957,-0.04981
100.01000,9.43957,-0.04975
100.21000,9.43957,-0.04973
100.41000,9.43957,-0.04965
100.61000,9.43957,-0.04963
100.81000,9.43957,-0.04956
101.01000,9.43957,-0.04950
101.21000,9.43957,-0.04944
101.41000,9.43957,-0.04937
101.61000,9.43957,-0.04934
101.81000,9.43957,-0.04928
102.01000,9.43957,-0.04922
102.21000,9.43957,-0.04919
102.41000,9.43957,-0.04911
102.61000,9.43957,-0.04906
102.81000,9.43957,-0.04898
103.01000,9.43957,-0.04897
103.21000,9.43957,-0.04892
103.41000,9.43957,-0.04888
103.61000,9.43957,-0.04882
103.81000,9.43957,-0.04880
104.01000,9.43957,-0.04871
104.21000,9.43957,-0.04864
104.41000,9.43957,-0.04859
104.61000,9.43957,-0.04856
104.81000,9.43957,-0.04853
105.01000,9.43957,-0.04843
105.21000,9.43957,-0.04840
105.41001,9.43957,-0.04835
105.61001,9.43957,-0.04829
105.81001,9.43957,-0.04824
106.01001,9.43957,-0.04822
106.21001,9.43957,-0.04816
106.41001,9.43957,-0.04813
106.61001,9.43957,-0.04806
106.81001,9.43957,-0.04799
107.01001,9.43957,-0.04796
107.21001,9.43957,-0.04793
107.41001,9.43957,-0.04791
107.61001,9.43957,-0.04785
107.81001,9.43957,-0.04780
108.01001,9.43957,-0.04777
108.21001,9.43957,-0.04771
108.41001,9.43957,-0.04767
108.61001,9.43957,-0.04762
108.81001,9.43957,-0.04759
109.01001,9.43957,-0.04752
109.21001,9.43957,-0.04749
109.41001,9.43957,-0.04747
109.61001,9.43957,-0.04736
109.81001,9.43957,-0.04736
110.01001,9.43957,-0.04735
110.21001,9.43957,-0.04727
110.41001,9.43957,-0.04721
110.61001,9.43957,-0.04725
110.81001,9.43957,-0.04714
111.01001,9.43957,-0.04707
111.21001,9.43957,-0.04710
111.41001,9.43957,-0.04705
111.61001,9.43957,-0.04700
111.81001,9.43957,-0.04699
112.01001,9.43957,-0.04693
112.21001,9.43957,-0.04688
112.41001,9.43957,-0.04685
112.61001,9.43957,-0.04680
112.81001,9.43957,-0.04677
113.01001,9.43957,-0.04670
113.21001,9.43957,-0.04670
113.41001,9.43957,-0.04665
113.61001,9.43957,-0.04660
113.81001,9.43957,-0.04655
114.01001,9.43957,-0.04649
114.21001,9.43957,-0.04645
114.41001,9.43957,-0.04642
114.61001,9.43957,-0.04637
114.81001,9.43957,-0.04634
115.01001,9.43957,-0.04628
115.21001,9.43957,-0.04624
115.41001,9.43957,-0.04623
115.61001,9.43957,-0.04616
115.81001,9.43957,-0.04610
116.01001,9.43957,-0.04607
116.21001,9.43957,-0.04601
116.41001,9.43957,-0.04600
116.61001,9.43957,-0.04597
116.81001,9.43957,-0.04588
117.01001,9.43957,-0.04586
117.21001,9.43957,-0.04583
117.41001,9.43957,-0.04579
117.61001,9.43957,-0.04575
117.81001,9.43957,-0.04571
118.01001,9.43957,-0.04567
118.21001,9.43957,-0.04562
118.41001,9.43957,-0.04560
118.61001,9.43957,-0.04558
118.81001,9.43957,-0.04551
119.01001,9.43957,-0.04546
119.21001,9.43957,-0.04543
119.41001,9.43957,-0.04541
119.61001,9.43957,-0.04538
119.81001,9.43957,-0.04532
120.01001,9.43957,-0.04527
120.21001,9.43957,-0.04523
120.41001,9.43957,-0.04521
120.61001,9.43957,-0.04523
120.81001,9.43957,-0.04513
121.01001,9.43957,-0.04510
121.21001,9.43957,-0.04512
121.41001,9.43957,-0.04505
121.61001,9.43957,-0.04504
121.81001,9.43957,-0.04498
122.01001,9.43957,-0.04497
122.21001,9.43957,-0.04491
122.41001,9.43957,-0.04491
122.61001,9.43957,-0.04487
122.81001,9.43957,-0.04489
123.01001,9.43957,-0.04480
123.21001,9.43957,-0.04478
123.41001,9.43957,-0.04474
123.61001,9.43957,-0.04471
123.81001,9.43957,-0.04469
124.01001,9.43957,-0.04467
124.21001,9.43957,-0.04461
124.41001,9.43957,-0.04457
124.61001,9.43957,-0.04457
124.81001,9.43957,-0.04454
125.01001,9.43957,-0.04450
125.21001,9.43957,-0.04450
125.41001,9.43957,-0.04443
125.61001,9.43957,-0.04442
125.81001,9.43957,-0.04440
126.01001,9.43957,-0.04435
126.21001,9.43957,-0.04430
126.41001,9.43957,-0.04429
126.61001,9.43957,-0.04425
126.81001,9.43957,-0.04421
127.01001,9.43957,-0.04415
127.21001,9.43957,-0.04410
127.41001,9.43957,-0.04409
127.61001,9.43957,-0.04406
127.81001,9.43957,-0.04402
128.01001,9.43957,-0.04398
128.21001,9.43957,-0.04396
128.41001,9.43957,-0.04389
128.61001,9.43957,-0.04389
128.81001,9.43957,-0.04381
129.01001,9.43957,-0.04379
129.21001,9.43957,-0.04375
129.41001,9.43957,-0.04377
129.61001,9.43957,-0.04370
129.81001,9.43957,-0.04367
130.01001,9.43957,-0.04364
130.21001,9.43957,-0.04362
130.41001,9.43957,-0.04357
130.61001,9.43957,-0.04354
130.81001,9.43957,-0.04350
131.01001,9.43957,-0.04346
131.21001,9.43957,-0.04347
131.41001,9.43957,-0.04343
131.61001,9.43957,-0.04341
131.81001,9.43957,-0.04338
132.01001,9.43957,-0.04330
132.21001,9.43957,-0.04334
132.41001,9.43957,-0.04327
132.61001,9.43957,-0.04328
132.81001,9.43957,-0.04320
133.01001,9.43957,-0.04321
133.21001,9.43957,-0.04321
133.41001,9.43957,-0.04318
133.61001,9.43957,-0.04314
133.81001,9.43957,-0.04312
134.01001,9.43957,-0.04306
134.21001,9.43957,-0.04306
134.41001,9.43957,-0.04304
134.61001,9.43957,-0.04299
134.81001,9.43957,-0.04296
135.01001,9.43957,-0.04294
135.21001,9.43957,-0.04294
135.41001,9.43957,-0.04292
135.61001,9.43957,-0.04287
135.81001,9.43957,-0.04284
136.01001,9.43957,-0.04277
136.21001,9.43957,-0.04284
136.41001,9.43957,-0.04283
136.61001,9.43957,-0.04279
136.81001,9.43957,-0.04272
137.01001,9.43957,-0.04273
137.21001,9.43957,-0.04266
137.41001,9.43957,-0.04262
137.61001,9.43957,-0.04259
137.81001,9.43957,-0.04257
138.01001,9.43957,-0.04256
138.21001,9.43957,-0.04253
138.41001,9.43957,-0.04250
138.61001,9.43957,-0.04246
138.81001,9.43957,-0.04243
139.01001,9.43957,-0.04238
139.21001,9.43957,-0.04233
139.41001,9.43957,-0.04235
139.61001,9.43957,-0.04230
139.81001,9.43957,-0.04225
140.01001,9.43957,-0.04223
140.21001,9.43957,-0.04218
140.41001,9.43957,-0.04217
140.61001,9.43957,-0.04213
140.81001,9.43957,-0.04213
141.01001,9.43957,-0.04212
141.21001,9.43957,-0.04207
141.41001,9.43957,-0.04203
141.61001,9.43957,-0.04205
141.81001,9.43957,-0.04199
142.01001,9.43957,-0.04197
142.21001,9.43957,-0.04193
142.41001,9.43957,-0.04194
142.61001,9.43957,-0.04185
142.81001,9.43957,-0.04184
143.01001,9.43957,-0.04182
143.21001,9.43957,-0.04180
143.41001,9.43957,-0.04174
143.61001,9.43957,-0.04170
143.81001,9.43957,-0.04170
144.01001,9.43957,-0.04166
144.21001,9.43957,-0.04165
144.41001,9.43957,-0.04161
144.61001,9.43957,-0.04160
144.81001,9.43957,-0.04154
145.01001,9.43957,-0.04153
145.21001,9.43957,-0.04154
145.41001,9.43957,-0.04147
145.61001,9.43957,-0.04150
145.81001,9.43957,-0.04141
146.01001,9.43957,-0.04139
146.21001,9.43957,-0.04136
146.41001,9.43957,-0.04139
146.61001,9.43957,-0.04129
146.81001,9.43957,-0.04125
147.01001,9.43957,-0.04121
147.21001,9.43957,-0.04122
147.41001,9.43957,-0.04113
147.61001,9.43957,-0.04113
147.81001,9.43957,-0.04111
148.01001,9.43957,-0.04110
148.21001,9.43957,-0.04105
148.41001,9.43957,-0.04103
148.61001,9.43957,-0.04101
148.81001,9.43957,-0.04099
149.01001,9.43957,-0.04097
149.21001,9.43957,-0.04098
149.41001,9.43957,-0.04094
149.61001,9.43957,-0.04089
149.81001,9.43957,-0.04086
150.01001,9.43957,-0.04084
150.21001,9.43957,-0.04079
150.41001,9.43957,-0.04080
150.61001,9.43957,-0.04076
150.81001,9.43957,-0.04073
151.01001,9.43957,-0.04067
151.21001,9.43957,-0.04069
151.41001,9.43957,-0.04066
151.61001,9.43957,-0.04061
151.81001,9.43957,-0.04061
152.01001,9.43957,-0.04056
152.21001,9.43957,-0.04055
152.41001,9.43957,-0.04051
152.61001,9.43957,-0.04053
152.81001,9.43957,-0.04050
153.01001,9.43957,-0.04045
153.21001,9.43957,-0.04043
153.41001,9.43957,-0.04037
153.61001,9.43957,-0.04037
153.81001,9.43957,-0.04036
154.01001,9.43957,-0.04032
154.21001,9.43957,-0.04026
154.41001,9.43957,-0.04029
154.61001,9.43957,-0.04024
154.81001,9.43957,-0.04021
155.01001,9.43957,-0.04019
155.21001,9.43957,-0.04019
155.41001,9.43957,-0.04012
155.61001,9.43957,-0.04012
155.81001,9.43957,-0.04005
156.01001,9.43957,-0.04005
156.21001,9.43957,-0.04005
156.41001,9.43957,-0.04004
156.61001,9.43957,-0.03999
156.81001,9.43957,-0.03995
157.01001,9.43957,-0.03995
157.21001,9.43957,-0.03990
157.41001,9.43957,-0.03988
157.61001,9.43957,-0.03988
157.81001,9.43957,-0.03985
158.01001,9.43957,-0.03979
158.21001,9.43957,-0.03981
158.41001,9.43957,-0.03980
158.61001,9.43957,-0.03977
158.81001,9.43957,-0.03978
159.01001,9.43957,-0.03972
159.21001,9.43957,-0.03971
159.41001,9.43957,-0.03965
159.61001,9.43957,-0.03962
159.81001,9.43957,-0.03962
160.01001,9.43957,-0.03959
160.21001,9.43957,-0.03960
160.41001,9.43957,-0.03954
160.61001,9.43957,-0.03955
160.81001,9.43957,-0.03950
161.01001,9.43957,-0.03952
161.21001,9.43957,-0.03946
161.41001,9.43957,-0.03945
161.61001,9.43957,-0.03945
161.81001,9.43957,-0.03944
162.01001,9.43957,-0.03939
162.21001,9.43957,-0.03936
162.41001,9.43957,-0.03935
162.61001,9.43957,-0.03936
162.81001,9.43957,-0.03932
163.01001,9.43957,-0.03928
163.21001,9.43957,-0.03930
163.41001,9.43957,-0.03926
163.61001,9.43957,-0.03923
163.81001,9.43957,-0.03921
164.01001,9.43957,-0.03923
164.21001,9.43957,-0.03920
164.41001,9.43957,-0.03917
164.61001,9.43957,-0.03919
164.81001,9.43957,-0.03920
165.01001,9.43957,-0.03917
165.21001,9.43957,-0.03913
165.41001,9.43957,-0.03912
165.61001,9.43957,-0.03911
165.81001,9.43957,-0.03910
166.01001,9.43957,-0.03905
166.21001,9.43957,-0.03906
166.41001,9.43957,-0.03903
166.61001,9.43957,-0.03900
166.81001,9.43957,-0.03897
167.01001,9.43957,-0.03898
167.21001,9.43957,-0.03896
167.41001,9.43957,-0.03890
167.61001,9.43957,-0.03889
167.81001,9.43957,-0.03891
168.01001,9.43957,-0.03889
168.21001,9.43957,-0.03883
168.41001,9.43957,-0.03881
168.61001,9.43957,-0.03883
168.81001,9.43957,-0.03879
169.01001,9.43957,-0.03879
169.21001,9.43957,-0.03875
169.41001,9.43957,-0.03873
169.61001,9.43957,-0.03870
169.81001,9.43957,-0.03869
170.01001,9.43957,-0.03865
170.21001,9.43957,-0.03865
170.41001,9.43957,-0.03860
170.61001,9.43957,-0.03861
170.81001,9.43957,-0.03858
171.01001,9.43957,-0.03855
171.21001,9.43957,-0.03855
171.41001,9.43957,-0.03848
171.61001,9.43957,-0.03850
171.81001,9.43957,-0.03845
172.01001,9.43957,-0.03845
172.21001,9.43957,-0.03847
172.41001,9.43957,-0.03841
172.61001,9.43957,-0.03843
172.81001,9.43957,-0.03839
173.01001,9.43957,-0.03838
173.21001,9.43957,-0.03832
173.41001,9.43957,-0.03835
173.61001,9.43957,-0.03832
173.81001,9.43957,-0.03830
174.01001,9.43957,-0.03830
174.21001,9.43957,-0.03823
174.41001,9.43957,-0.03834
174.61001,9.43957,-0.03836
174.81001,9.43957,-0.03832
175.01001,9.43957,-0.03831
175.21001,9.43957,-0.03828
175.41001,9.43957,-0.03827
175.61001,9.43957,-0.03823
175.81001,9.43957,-0.03819
176.01001,9.43957,-0.03820
176.21001,9.43957,-0.03814
176.41001,9.43957,-0.03812
176.61001,9.43957,-0.03811
176.81001,9.43957,-0.03806
177.01001,9.43957,-0.03806
177.21001,9.43957,-0.03805
177.41001,9.43957,-0.03802
177.61001,9.43957,-0.03797
177.81001,9.43957,-0.03798
178.01001,9.43957,-0.03795
178.21001,9.43957,-0.03793
178.41001,9.43957,-0.03788
178.61001,9.43957,-0.03789
178.81001,9.43957,-0.03786
179.01001,9.43957,-0.03785
179.21001,9.43957,-0.03782
179.41001,9.43957,-0.03783
179.61001,9.43957,-0.03779
179.81001,9.43957,-0.03778
180.01001,9.43957,-0.03773
180.21001,9.43957,-0.03774
180.41001,9.43957,-0.03769
180.61001,9.43957,-0.03768
180.81001,9.43957,-0.03768
181.01001,9.43957,-0.03763
181.21001,9.43957,-0.03759
181.41001,9.43957,-0.03761
181.61001,9.43957,-0.03754
181.81001,9.43957,-0.03757
182.01001,9.43957,-0.03756
182.21001,9.43957,-0.03753
182.41001,9.43957,-0.03751
182.61001,9.43957,-0.03746
182.81001,9.43957,-0.03750
183.01001,9.43957,-0.03743
183.21001,9.43957,-0.03743
183.41001,9.43957,-0.03743
183.61001,9.43957,-0.03740
183.81001,9.43957,-0.03736
184.01001,9.43957,-0.03735
184.21001,9.43957,-0.03732
184.41001,9.43957,-0.03727
184.61001,9.43957,-0.03731
184.81001,9.43957,-0.03725
185.01001,9.43957,-0.03726
185.21001,9.43957,-0.03725
185.41001,9.43957,-0.03723
185.61001,9.43957,-0.03719
185.81001,9.43957,-0.03717
186.01001,9.43957,-0.03722
186.21001,9.43957,-0.03716
186.41001,9.43957,-0.03711
186.61001,9.43957,-0.03707
186.81001,9.43957,-0.03710
187.01001,9.43957,-0.03703
187.21001,9.43957,-0.03706
187.41001,9.43957,-0.03702
187.61001,9.43957,-0.03704
187.81001,9.43957,-0.03700
188.01001,9.43957,-0.03697
188.21001,9.43957,-0.03695
188.41001,9.43957,-0.03695
188.61001,9.43957,-0.03693
188.81001,9.43957,-0.03690
189.01001,9.43957,-0.03687
189.21001,9.43957,-0.03686
189.41001,9.43957,-0.03683
189.61001,9.43957,-0.03681
189.81001,9.43957,-0.03680
190.01001,9.43957,-0.03678